Workbook

Sheet Invoice
A1: Supplier Invoice
A2: Fuzhou Enxin International Business Co.,Ltd ADD: Builing 2, Jinniu Mountain Internet Industrial Park, No.528 Xihong Road, Gulou District, Fuzhou 35002, China Contact:Sammie TEL: +86 13599449150 | J2: HS Code | L2: Country | M2: HS Code
A3: Commercial Invoice | J3: {=INDEX($M$3:$M$15,MATCH($F$6,L$3:L$15,0))} -> hs_code_uk | L3: US | M3: hs_code_us
A4: INVOICE NO: | B4: PO-55UKWK1 ,PO-55UKWK2 | E4: DATE: | F4: Jun. 30th 2026 | L4: UK | M4: hs_code_uk
A5: CONSIGNEE: | B5: =_xlfn.IFNA(INDEX(Country!$C$3:$O$3,MATCH($F$6,Country!$C$2:$O$2,0)),"") -> Dock & Bay LTD 3rd Floor 86-90 Paul Street, London, England, EC2A 4NE Attn: Ben Muller ben@dockandbay.com +61 404 637 403 Tax number: GB212507156 | E5: Payment Term: | F5: TT | L5: EU | M5: hs_code_eu
E6: Delivery Country: | F6: UK | L6: AU | M6: hs_code_au
E7: Delivery Term: | F7: FOB | L7: Spain - DISTRIBUCIONES XKI SL | M7: hs_code_eu
E8: Country of Origin: | F8: China | L8: Thailand - Make My Day | M8: hs_code_us
A9: NOTIFY PARTY: | B9: =_xlfn.IFNA(INDEX(Country!$C$4:$O$4,MATCH($F$6,Country!$C$2:$O$2,0)),"") -> ILG c/o Dock & Bay Unit 2 Space Gatwick Faraday Road Crawley RH10 9BJ Ph: 07960 100 293 Attn: Aaron Hale aaronh@ilguk.com | E9: Port of Loading: | F9: Xiamen Gaoqi International Airport, China | L9: Switzerland - Trendform AG | M9: hs_code_eu
E10: Port of Discharge: | L10: Greece - A-Play | M10: hs_code_eu
A11: SKU | B11: CERTIFICATION | C11: Recycled Content | D11: DESCRIPTION OF GOODS & FIBRE COMPOSITION | E11: HS Code | F11: Q'TY (PCS) | G11: Unit Price FOB (USD/PCS) | H11: AMOUNT (USD) | L11: Estibol | M11: hs_code_us
L12: Direct to Client | M12: hs_code_us
A13: BAGDRY-XS-WYWH | B13: =IFERROR(IF(ISNUMBER(SEARCH("GRS Certified",VLOOKUP(A13,[1]SKU_LOOKUP!A:I,9,FALSE))),"GRS",""),"") | C13: =IFERROR(IF(ISNUMBER(SEARCH("GRS Certified",VLOOKUP(A13,[1]SKU_LOOKUP!A:I,9,FALSE))),100%,""),"") | D13: =_xlfn.IFNA(INDEX(SKU_LOOKUP!M2:M2556,MATCH(Invoice!A13,SKU_LOOKUP!A2:A2556,0)),"") -> Small Dry Bag 80% polyester, 20% polyurethane (PU) | E13: =_xlfn.IFNA(INDEX([1]SKU_LOOKUP!$M$2:$S950,MATCH($A13,[1]SKU_LOOKUP!$A$2:$A950,0),MATCH($J$3,[1]SKU_LOOKUP!$M$1:$S$1,0)),"") -> 4202220000 | F13: 400 | G13: 2.73 | H13: =F13*G13 -> 1092 | L13: Australia - Until | M13: hs_code_au
A14: BAGDRY-XS-NAVY | B14: =IFERROR(IF(ISNUMBER(SEARCH("GRS Certified",VLOOKUP(A14,[1]SKU_LOOKUP!A:I,9,FALSE))),"GRS",""),"") | C14: =IFERROR(IF(ISNUMBER(SEARCH("GRS Certified",VLOOKUP(A14,[1]SKU_LOOKUP!A:I,9,FALSE))),100%,""),"") | D14: =_xlfn.IFNA(INDEX(SKU_LOOKUP!M3:M2557,MATCH(Invoice!A14,SKU_LOOKUP!A3:A2557,0)),"") -> Small Dry Bag 80% polyester, 20% polyurethane (PU) | E14: =_xlfn.IFNA(INDEX([1]SKU_LOOKUP!$M$2:$S951,MATCH($A14,[1]SKU_LOOKUP!$A$2:$A951,0),MATCH($J$3,[1]SKU_LOOKUP!$M$1:$S$1,0)),"") -> 4202220000 | F14: 500 | G14: 2.73 | H14: =F14*G14 -> 1365
B15: =IFERROR(IF(ISNUMBER(SEARCH("GRS Certified",VLOOKUP(A15,[1]SKU_LOOKUP!A:I,9,FALSE))),"GRS",""),"") | C15: =IFERROR(IF(ISNUMBER(SEARCH("GRS Certified",VLOOKUP(A15,[1]SKU_LOOKUP!A:I,9,FALSE))),100%,""),"") | D15: =_xlfn.IFNA(INDEX(SKU_LOOKUP!M9:M2563,MATCH(Invoice!A15,SKU_LOOKUP!A9:A2563,0)),"") | E15: =_xlfn.IFNA(INDEX([1]SKU_LOOKUP!$M$2:$S957,MATCH($A15,[1]SKU_LOOKUP!$A$2:$A957,0),MATCH($J$3,[1]SKU_LOOKUP!$M$1:$S$1,0)),"") | H15: =F15*G15 -> 0
B16: =IFERROR(IF(ISNUMBER(SEARCH("GRS Certified",VLOOKUP(A16,[1]SKU_LOOKUP!A:I,9,FALSE))),"GRS",""),"") | C16: =IFERROR(IF(ISNUMBER(SEARCH("GRS Certified",VLOOKUP(A16,[1]SKU_LOOKUP!A:I,9,FALSE))),100%,""),"") | D16: =_xlfn.IFNA(INDEX(SKU_LOOKUP!M10:M2564,MATCH(Invoice!A16,SKU_LOOKUP!A10:A2564,0)),"") | E16: =_xlfn.IFNA(INDEX([1]SKU_LOOKUP!$M$2:$S958,MATCH($A16,[1]SKU_LOOKUP!$A$2:$A958,0),MATCH($J$3,[1]SKU_LOOKUP!$M$1:$S$1,0)),"") | H16: =F16*G16 -> 0
B17: =IFERROR(IF(ISNUMBER(SEARCH("GRS Certified",VLOOKUP(A17,[1]SKU_LOOKUP!A:I,9,FALSE))),"GRS",""),"") | C17: =IFERROR(IF(ISNUMBER(SEARCH("GRS Certified",VLOOKUP(A17,[1]SKU_LOOKUP!A:I,9,FALSE))),100%,""),"") | D17: =_xlfn.IFNA(INDEX(SKU_LOOKUP!M11:M2565,MATCH(Invoice!A17,SKU_LOOKUP!A11:A2565,0)),"") | E17: =_xlfn.IFNA(INDEX([1]SKU_LOOKUP!$M$2:$S959,MATCH($A17,[1]SKU_LOOKUP!$A$2:$A959,0),MATCH($J$3,[1]SKU_LOOKUP!$M$1:$S$1,0)),"") | H17: =F17*G17 -> 0
B18: =IFERROR(IF(ISNUMBER(SEARCH("GRS Certified",VLOOKUP(A18,[1]SKU_LOOKUP!A:I,9,FALSE))),"GRS",""),"") | C18: =IFERROR(IF(ISNUMBER(SEARCH("GRS Certified",VLOOKUP(A18,[1]SKU_LOOKUP!A:I,9,FALSE))),100%,""),"") | D18: =_xlfn.IFNA(INDEX(SKU_LOOKUP!M12:M2566,MATCH(Invoice!A18,SKU_LOOKUP!A12:A2566,0)),"") | E18: =_xlfn.IFNA(INDEX([1]SKU_LOOKUP!$M$2:$S960,MATCH($A18,[1]SKU_LOOKUP!$A$2:$A960,0),MATCH($J$3,[1]SKU_LOOKUP!$M$1:$S$1,0)),"") | H18: =F18*G18 -> 0
B19: =IFERROR(IF(ISNUMBER(SEARCH("GRS Certified",VLOOKUP(A19,[1]SKU_LOOKUP!A:I,9,FALSE))),"GRS",""),"") | C19: =IFERROR(IF(ISNUMBER(SEARCH("GRS Certified",VLOOKUP(A19,[1]SKU_LOOKUP!A:I,9,FALSE))),100%,""),"") | D19: =_xlfn.IFNA(INDEX(SKU_LOOKUP!M13:M2567,MATCH(Invoice!A19,SKU_LOOKUP!A13:A2567,0)),"") | E19: =_xlfn.IFNA(INDEX([1]SKU_LOOKUP!$M$2:$S961,MATCH($A19,[1]SKU_LOOKUP!$A$2:$A961,0),MATCH($J$3,[1]SKU_LOOKUP!$M$1:$S$1,0)),"") | H19: =F19*G19 -> 0
B20: =IFERROR(IF(ISNUMBER(SEARCH("GRS Certified",VLOOKUP(A20,[1]SKU_LOOKUP!A:I,9,FALSE))),"GRS",""),"") | C20: =IFERROR(IF(ISNUMBER(SEARCH("GRS Certified",VLOOKUP(A20,[1]SKU_LOOKUP!A:I,9,FALSE))),100%,""),"") | D20: =_xlfn.IFNA(INDEX(SKU_LOOKUP!M14:M2568,MATCH(Invoice!A20,SKU_LOOKUP!A14:A2568,0)),"") | E20: =_xlfn.IFNA(INDEX([1]SKU_LOOKUP!$M$2:$S962,MATCH($A20,[1]SKU_LOOKUP!$A$2:$A962,0),MATCH($J$3,[1]SKU_LOOKUP!$M$1:$S$1,0)),"") | H20: =F20*G20 -> 0
B21: =IFERROR(IF(ISNUMBER(SEARCH("GRS Certified",VLOOKUP(A21,[1]SKU_LOOKUP!A:I,9,FALSE))),"GRS",""),"") | C21: =IFERROR(IF(ISNUMBER(SEARCH("GRS Certified",VLOOKUP(A21,[1]SKU_LOOKUP!A:I,9,FALSE))),100%,""),"") | D21: =_xlfn.IFNA(INDEX(SKU_LOOKUP!M15:M2569,MATCH(Invoice!A21,SKU_LOOKUP!A15:A2569,0)),"") | E21: =_xlfn.IFNA(INDEX([1]SKU_LOOKUP!$M$2:$S963,MATCH($A21,[1]SKU_LOOKUP!$A$2:$A963,0),MATCH($J$3,[1]SKU_LOOKUP!$M$1:$S$1,0)),"") | H21: =F21*G21 -> 0
B22: =IFERROR(IF(ISNUMBER(SEARCH("GRS Certified",VLOOKUP(A22,[1]SKU_LOOKUP!A:I,9,FALSE))),"GRS",""),"") | C22: =IFERROR(IF(ISNUMBER(SEARCH("GRS Certified",VLOOKUP(A22,[1]SKU_LOOKUP!A:I,9,FALSE))),100%,""),"") | D22: =_xlfn.IFNA(INDEX(SKU_LOOKUP!M16:M2570,MATCH(Invoice!A22,SKU_LOOKUP!A16:A2570,0)),"") | E22: =_xlfn.IFNA(INDEX([1]SKU_LOOKUP!$M$2:$S964,MATCH($A22,[1]SKU_LOOKUP!$A$2:$A964,0),MATCH($J$3,[1]SKU_LOOKUP!$M$1:$S$1,0)),"") | H22: =F22*G22 -> 0
B23: =IFERROR(IF(ISNUMBER(SEARCH("GRS Certified",VLOOKUP(A23,[1]SKU_LOOKUP!A:I,9,FALSE))),"GRS",""),"") | C23: =IFERROR(IF(ISNUMBER(SEARCH("GRS Certified",VLOOKUP(A23,[1]SKU_LOOKUP!A:I,9,FALSE))),100%,""),"") | D23: =_xlfn.IFNA(INDEX(SKU_LOOKUP!M17:M2571,MATCH(Invoice!A23,SKU_LOOKUP!A17:A2571,0)),"") | E23: =_xlfn.IFNA(INDEX([1]SKU_LOOKUP!$M$2:$S965,MATCH($A23,[1]SKU_LOOKUP!$A$2:$A965,0),MATCH($J$3,[1]SKU_LOOKUP!$M$1:$S$1,0)),"") | H23: =F23*G23 -> 0
B24: =IFERROR(IF(ISNUMBER(SEARCH("GRS Certified",VLOOKUP(A24,[1]SKU_LOOKUP!A:I,9,FALSE))),"GRS",""),"") | C24: =IFERROR(IF(ISNUMBER(SEARCH("GRS Certified",VLOOKUP(A24,[1]SKU_LOOKUP!A:I,9,FALSE))),100%,""),"") | D24: =_xlfn.IFNA(INDEX(SKU_LOOKUP!M18:M2572,MATCH(Invoice!A24,SKU_LOOKUP!A18:A2572,0)),"") | E24: =_xlfn.IFNA(INDEX([1]SKU_LOOKUP!$M$2:$S966,MATCH($A24,[1]SKU_LOOKUP!$A$2:$A966,0),MATCH($J$3,[1]SKU_LOOKUP!$M$1:$S$1,0)),"") | H24: =F24*G24 -> 0
B25: =IFERROR(IF(ISNUMBER(SEARCH("GRS Certified",VLOOKUP(A25,[1]SKU_LOOKUP!A:I,9,FALSE))),"GRS",""),"") | C25: =IFERROR(IF(ISNUMBER(SEARCH("GRS Certified",VLOOKUP(A25,[1]SKU_LOOKUP!A:I,9,FALSE))),100%,""),"") | D25: =_xlfn.IFNA(INDEX(SKU_LOOKUP!M19:M2573,MATCH(Invoice!A25,SKU_LOOKUP!A19:A2573,0)),"") | E25: =_xlfn.IFNA(INDEX([1]SKU_LOOKUP!$M$2:$S967,MATCH($A25,[1]SKU_LOOKUP!$A$2:$A967,0),MATCH($J$3,[1]SKU_LOOKUP!$M$1:$S$1,0)),"") | H25: =F25*G25 -> 0
B26: =IFERROR(IF(ISNUMBER(SEARCH("GRS Certified",VLOOKUP(A26,[1]SKU_LOOKUP!A:I,9,FALSE))),"GRS",""),"") | C26: =IFERROR(IF(ISNUMBER(SEARCH("GRS Certified",VLOOKUP(A26,[1]SKU_LOOKUP!A:I,9,FALSE))),100%,""),"") | D26: =_xlfn.IFNA(INDEX(SKU_LOOKUP!M20:M2574,MATCH(Invoice!A26,SKU_LOOKUP!A20:A2574,0)),"") | E26: =_xlfn.IFNA(INDEX([1]SKU_LOOKUP!$M$2:$S968,MATCH($A26,[1]SKU_LOOKUP!$A$2:$A968,0),MATCH($J$3,[1]SKU_LOOKUP!$M$1:$S$1,0)),"") | H26: =F26*G26 -> 0
... B34: =IFERROR(IF(ISNUMBER(SEARCH("GRS Certified",VLOOKUP(A34,[1]SKU_LOOKUP!A:I,9,FALSE))),"GRS",""),"") | C34: =IFERROR(IF(ISNUMBER(SEARCH("GRS Certified",VLOOKUP(A34,[1]SKU_LOOKUP!A:I,9,FALSE))),100%,""),"") | D34: =_xlfn.IFNA(INDEX(SKU_LOOKUP!M28:M2582,MATCH(Invoice!A34,SKU_LOOKUP!A28:A2582,0)),"") | E34: =_xlfn.IFNA(INDEX([1]SKU_LOOKUP!$M$2:$S976,MATCH($A34,[1]SKU_LOOKUP!$A$2:$A976,0),MATCH($J$3,[1]SKU_LOOKUP!$M$1:$S$1,0)),"") | H34: =F34*G34 -> 0
A35: Made in china | E35: Total: | F35: =SUM(F13:F34) -> 900 | H35: =SUM(H13:H34) -> 2457
A36: PS：Please pay the 50% before 17th,Dec,Total 15221.37USD Please pay the 51% before 16th,May, Total 15525.8 USD
A38: Signature： | G38: Signature：
A39: Seal: | G39: Seal:

Sheet Packing List
A1: Supplier Details
A2: Fuzhou Enxin International Business Co.,Ltd ADD: Builing 2, Jinniu Mountain Internet Industrial Park, No.528 Xihong Road, Gulou District, Fuzhou 35002, China Contact:Sammie TEL: +86 13599449150
A3: Packing List
A4: INVOICE NO: | B4: PO-55UKWK1 ,PO-55UKWK2 | E4: DATE: | F4: Jun. 30th 2026
A5: CONSIGNEE: | B5: =Invoice!B5 -> Dock & Bay LTD 3rd Floor 86-90 Paul Street, London, England, EC2A 4NE Attn: Ben Muller ben@dockandbay.com +61 404 637 403 Tax number: GB212507156 | E5: Payment Term: | F5: =Invoice!F5 -> TT
E7: Delivery Term: | F7: =Invoice!F7 -> FOB
E8: Country of Origin:
A9: NOTIFY PARTY: | B9: =Invoice!B9 -> ILG c/o Dock & Bay Unit 2 Space Gatwick Faraday Road Crawley RH10 9BJ Ph: 07960 100 293 Attn: Aaron Hale aaronh@ilguk.com | E9: Port of Loading: | F9: =Invoice!F9 -> Xiamen Gaoqi International Airport, China
E10: Port of Discharge:
A11: SKU | B11: SIZE(cm*cm) | C11: DESCRIPTION OF GOODS & FIBRE COMPOSITION | D11: Q'TY (CTN) | E11: Q'TY (PCS) | F11: GW(kg) | G11: Order Quantity | H11: short shipment
A13: BAGDRY-XS-WYWH | B13: 58*38*32 | C13: Small Dry Bag 80% polyester, 20% polyurethane (PU) | D13: 4 | E13: 400 | F13: 56.8 | G13: 400 | H13: 0
A14: BAGDRY-XS-NAVY | B14: 58*38*32 | C14: =_xlfn.IFNA(INDEX(SKU_LOOKUP!M2:M2557,MATCH('Packing List'!A14,SKU_LOOKUP!A3:A2557,0)),"") -> Small Dry Bag 80% polyester, 20% polyurethane (PU) | D14: 5 | E14: 500 | F14: 71 | G14: 500 | H14: 0
A15: =Invoice!A15 -> 0 | C15: =_xlfn.IFNA(INDEX(SKU_LOOKUP!M8:M2563,MATCH('Packing List'!A15,SKU_LOOKUP!A9:A2563,0)),"")
A16: =Invoice!A16 -> 0 | C16: =_xlfn.IFNA(INDEX(SKU_LOOKUP!M9:M2564,MATCH('Packing List'!A16,SKU_LOOKUP!A10:A2564,0)),"")
A17: =Invoice!A17 -> 0 | C17: =_xlfn.IFNA(INDEX(SKU_LOOKUP!M10:M2565,MATCH('Packing List'!A17,SKU_LOOKUP!A11:A2565,0)),"")
A18: =Invoice!A18 -> 0 | C18: =_xlfn.IFNA(INDEX(SKU_LOOKUP!M11:M2566,MATCH('Packing List'!A18,SKU_LOOKUP!A12:A2566,0)),"")
A19: =Invoice!A19 -> 0 | C19: =_xlfn.IFNA(INDEX(SKU_LOOKUP!M12:M2567,MATCH('Packing List'!A19,SKU_LOOKUP!A13:A2567,0)),"")
A20: =Invoice!A20 -> 0 | C20: =_xlfn.IFNA(INDEX(SKU_LOOKUP!M13:M2568,MATCH('Packing List'!A20,SKU_LOOKUP!A14:A2568,0)),"")
A21: =Invoice!A21 -> 0 | C21: =_xlfn.IFNA(INDEX(SKU_LOOKUP!M14:M2569,MATCH('Packing List'!A21,SKU_LOOKUP!A15:A2569,0)),"")
A22: =Invoice!A22 -> 0 | C22: =_xlfn.IFNA(INDEX(SKU_LOOKUP!M15:M2570,MATCH('Packing List'!A22,SKU_LOOKUP!A16:A2570,0)),"")
A23: =Invoice!A23 -> 0 | C23: =_xlfn.IFNA(INDEX(SKU_LOOKUP!M16:M2571,MATCH('Packing List'!A23,SKU_LOOKUP!A17:A2571,0)),"")
A24: =Invoice!A24 -> 0 | C24: =_xlfn.IFNA(INDEX(SKU_LOOKUP!M17:M2572,MATCH('Packing List'!A24,SKU_LOOKUP!A18:A2572,0)),"")
A25: =Invoice!A25 -> 0 | C25: =_xlfn.IFNA(INDEX(SKU_LOOKUP!M18:M2573,MATCH('Packing List'!A25,SKU_LOOKUP!A19:A2573,0)),"")
A26: =Invoice!A26 -> 0 | C26: =_xlfn.IFNA(INDEX(SKU_LOOKUP!M19:M2574,MATCH('Packing List'!A26,SKU_LOOKUP!A20:A2574,0)),"")
... A34: =Invoice!A34 -> 0 | C34: =_xlfn.IFNA(INDEX(SKU_LOOKUP!M27:M2582,MATCH('Packing List'!A34,SKU_LOOKUP!A28:A2582,0)),"")
A35: Made in china | C35: Total: | D35: =SUM(D13:D34) -> 9 | E35: =SUM(E13:E34) -> 900 | F35: =SUM(F13:F34) -> 127.8 | G35: =SUM(G13:G34) -> 900 | H35: =SUM(H13:H34) -> 0
A36: Signature： | E36: Signature：
A37: Seal: | E37: Seal:

Sheet HS Codes
A1: SKU | B1: Product Name | C1: import_invoice_title | D1: hs_code_6_digits | E1: hs_code_us | F1: hs_code_uk | G1: hs_code_ca | H1: hs_code_eu | I1: hs_code_eu_sanction | J1: hs_code_au | K1: hs_code_dubai | N1: Country | O1: HS Code
A2: BAG-BEACH | B2: Beach Bag | C2: Beach Bag made from 100% polyester | D2: 420292 | E2: 4202.92.9100 | F2: 4202220000 | H2: 42022290 | J2: 4202.22.00 | K2: 42029100 | N2: US | O2: hs_code_us
A3: BAG-COOL | B3: Cooling Bag | C3: Insulated Food or Beverage Bag Outer: 80% polyester, 20% PEVA | D3: 420292 | E3: 4202.92.9100 | F3: 4202220000 | H3: 42022290 | J3: 4202.22.00 | N3: UK | O3: hs_code_uk
A4: BAG-DRY-MD | B4: Dry Bag | C4: Medium Dry Bag 80% TPU, 20% polyester | D4: 420292 | E4: 4202.92.9100 | F4: 4202220000 | H4: 42022290 | J4: 4202.22.00 | N4: EU | O4: hs_code_eu
A5: BAG-DRY-SM | B5: Dry Bag | C5: Small Dry Bag 80% polyester, 20% polyurethane (PU) | D5: 420292 | E5: 4202.92.9100 | F5: 4202220000 | H5: 42022290 | J5: 4202.22.00 | N5: AU | O5: hs_code_au
A6: BAG-FOLD | B6: Foldable Bag | C6: Shopping Bag 100% recycled polyester | D6: 420292 | E6: 4202.92.91.00 | F6: 4202921900 | G6: 4202.92.90.00 | H6: 4202 9298 90 | J6: 4202.92.90 | K6: 42029100
A7: BAG-TOILETRY | B7: Cosmetic Bag | C7: Toiletry Bag made of 100% polyester | D7: 420292 | E7: 4202929100 | F7: 4202220000 | H7: 4202929100
A8: BALLAST-PILLOW | B8: Ballast x Dock & Bay Pillow | C8: Pillow 100% recycled polyester (no cotton) | D8: 3926.9 | E8: 9404.90.2090 | F8: 63079098990 | G8: 3926.90.7500 | H8: 3926.90.7500 | J8: 6306.40.00
A9: BOTTL | B9: Bottles | C9: Bottle | D9: 731029 | E9: 7310.29.00 | F9: 7310299000 | G9: 7310.29.00 | H9: 73102191 | J9: 7310.21.10
A10: COOL | B10: Cooling Towels | C10: Fitness Towel - Toilet Linen 100% recycled polyester includes cotton on the packing pouch drawstring | D10: 630293 | E10: 6302.93.2000 | F10: 6302939000 | G10: 6302939000 | H10: 6302939000 | J10: 6302.29.00
A11: DOGTWL | B11: Towels - Dog | C11: Pet Towel - Toilet Linen 100% recycled 220 GSM/83% polyester/17% polyamide includes cotton on the packing pouch drawstring | D11: 630293 | E11: 6302.93.2000 | F11: 6302600090 | G11: 6302.93.00.00 | H11: 6302939000 | J11: 6302.39.00 | K11: 6507
A12: EYEMASK | B12: Eye Mask | C12: Sleeping Eye Cover 30% DuPont Sorona and 70% polyester. The eye cover fabric is 100% polyester (no cotton) | D12: 630790 | E12: 6307.90.9891 | F12: 6307909891
A13: GIFT-BOX-BEAUTY | B13: Gift Box - Hair Wrap & Makeup Remover | C13: Makeup Wipe (100% recycled polyester), Hair Towel (100% recycled 200 GSM/83% polyester/17% polyamide) (no cotton) | D13: 650500 | E13: 6504.00.90.15 | F13: 6505009090 | G13: 6505.00.40.00 | H13: 6505.00.90.90 | J13: 6505.00.90
A14: GIFT-BOX-BEAUTY-WAFFLE | B14: Gift Box - Hair Wrap & Makeup Remover | C14: Makeup Remover (100% recycled polyester), Hairwrap (100% recycled 200 GSM/83% polyester/17% polyamide) (no cotton) | D14: 650500 | E14: 6504.00.90.15 | F14: 6505009090 | G14: 6505.00.40.00 | H14: 6505.00.90.90 | J14: 6505.00.90
A15: GIFT-BOX-HAIR | B15: Gift Box | C15: Makeup Remover (100% recycled polyester), Hairwrap (100% recycled 200 GSM/83% polyester/17% polyamide) (no cotton) | D15: 650500 | E15: 6504.00.90.15 | F15: 6505009090 | G15: 6505.00.40.00 | H15: 6505.00.90.90 | J15: 6505.00.90
A16: GIFT-BOX-HOME | B16: Gift Box - Hair Wrap, Eye Mask, Toiletry Bag and Makeup Removers | C16: Makeup Wipe (100% recycled polyester), Hair Towel (100% recycled 200 GSM/83% polyester/17% polyamide) Toiletry Bag RPET canvas (no cotton) | D16: 650500 | E16: 6504.00.90.15 | F16: 6505009090 | G16: 6505.00.40.00 | H16: 6505.00.90.90 | J16: 6505.00.90
A17: HAIRW-premium | B17: Hair Wraps - Waffle | C17: Head Towel 100% recycled 340 GSM/83% polyester/17% polyamide (no cotton) | D17: 650500 | E17: 6504.00.90.15 | F17: 6505009090 | G17: 6505.00.40.00 | H17: 6505.00.90.90 | J17: 6505.00.90 | K17: 6507
A18: HAIRW-standard | B18: Hair Wraps - Suede | C18: Head Towel 100% recycled 200 GSM/83% polyester/17% polyamide (no cotton) | D18: 650500 | E18: 6504.00.90.15 | F18: 6505009090 | G18: 6505.00.40.00 | H18: 6505.00.90.90 | J18: 6505.00.90
A19: MAKUP | B19: Makeup Removers | C19: Makeup Wipe 100% recycled polyester (no cotton) | D19: 961620 | E19: 9616.20.00.00 | F19: 9616200000 | G19: 9616.20.00.00 | H19: 9616200000 | J19: 9616.20.00
A20: PICNIC | B20: Picnic Blanket | C20: Travelling Rug 100% recycled. BOTTOM: 100% polyester. TOP: 220 GSM/83% polyester/17% polyamide includes cotton on the packing pouch drawstring | D20: 630140 | E20: 6301.40.0020 | F20: 6301409099 | G20: 6301.40.0020 | H20: 6301409099 | J20: 6301.40.00 | K20: 6301
A21: PONCHA | B21: Poncho - Adults | C21: Beach Robe or Cloak 100% recycled 220 GSM/83% polyester/17% polyamide includes cotton on the packing pouch drawstring | D21: 610130 | E21: 6101.90.90.30 | F21: 6101309000 | G21: 6112399000 | H21: 6211 4390 00 | I21: 6117109000 | J21: 6112.39.00 | K21: 6202
A22: PONCHK | B22: Poncho - Kids | C22: Beach Robe or Cloak 100% recycled 220 GSM/83% polyester/17% polyamide includes cotton on the packing pouch drawstring | D22: 610130 | E22: 6101.90.90.30 | F22: 6101309000 | G22: 6112399000 | H22: 6211 4390 00 | I22: 6117109000 | J22: 6112.39.00 | K22: 6202
A23: ROBE | B23: Bath Robe | C23: Bathrobe 100% recycled 220 GSM/83% polyester/17% polyamide includes cotton on the packing pouch drawstring | D23: 610892 | E23: 6208.92.0010 | F23: 6208110000 | G23: 6208.92.00.00 | H23: 6208990099 | J23: 6208.11.00 | K23: 62089200
A24: SHORTS | B24: Swim Shorts | D24: 621111 | E24: 6112.31.00.10 | F24: 6112311000 | G24: 6112311000 | H24: 61123110 | J24: 6112.39.00 | K24: 61123100
A25: TEATWL | B25: Tea Towel | C25: Kitchen Linen 100% recycled 300 GSM/83% polyester/17% polyamide (no cotton) | D25: 630253 | E25: 6302.53.00.20 | F25: 6302531000 | G25: 6302531000 | H25: 63029310 | J25: 6302.53.00
A26: TOWLB | B26: Towels - Beach | C26: Beach Towel - Toilet Linen 100% recycled 220 GSM/83% polyester/17% polyamide includes cotton on the packing pouch drawstring | D26: 630293 | E26: 6302.93.2000 | F26: 6302600090 | G26: 6302.93.00.00 | H26: 63029390 | J26: 6302.39.00 | K26: 63029120
A27: TOWLB-KIDS | B27: Kids - Towels - Beach | C27: Beach Towel - Toilet Linen 100% recycled 220 GSM/83% polyester/17% polyamide includes cotton on the packing pouch drawstring | D27: 630293 | E27: 6302.93.2000 | F27: 6302600090 | G27: 6302.93.00.00 | H27: 6302939000 | J27: 6302.39.00 | K27: 63029120
A28: TOWLF | B28: Towels - Fitness | C28: Fitness Towels - Toilet Linen 100% recycled 220 GSM/83% polyester/17% polyamide (no cotton) | D28: 630293 | E28: 6302.93.2000 | F28: 6302600090 | G28: 6302.93.00.00 | H28: 6302939000 | J28: 6302.39.00 | K28: 63029120
A29: TOWLH | B29: Towels - Home | C29: Bath Towel - Toilet Linen 100% recycled 340 GSM/83% polyester/17% polyamide (no cotton) | D29: 630293 | E29: 6302.93.2000 | F29: 6302600090 | G29: 6302.93.00.00 | H29: 6302939000 | J29: 6302.39.00 | K29: 63029120
A30: BUNDLE-BABIATOR-TOWLB | B30: Babiators Bundle
A31: BUNDLE-BATH | B31: Bath Towels and Beauty Box
A32: BUNDLE-BEACH | B32: Beach Bundle - Beach Towel (2), Picnic Blanket, Dry Bag and Foldable Bag
A33: BUNDLE-BEACH-KIT-PICNIC-LG | B33: Picnic, Towel x 2 + Bag Bundle
A34: BUNDLE-BEACH-KIT-TOWLB-X2 | B34: Towel XXL, Towel x 2 + Bag Bundle
A35: BUNDLE-BEAUTY | B35: Beauty Box, Toiletry Bag and Eye Mask
A36: BUNDLE-COLLAB | B36: D&B x Somewhere Co - Beach Towel + Packing Cubes
A37: BUNDLE-FAMILY | B37: The Family Bundle - Beach Towels (2), Beach Pillows (2), Kids Beach Towels (2), Beach Bag, Picnic Blanket
A38: BUNDLE-FAMILY-PICNIC-XL | B38: Picnic XL, Towel x 4 + Bag Bundle
A39: BUNDLE-FITNESS | B39: The Fitness Bundle - Cooling Towel & Essential Towel
A40: BUNDLE-HOODT | B40: Baby Towel Bundle
...

Sheet SKU_LOOKUP
A1: SKU | B1: product_select | C1: GRS_material_product | D1: product_select_name | E1: product_category | F1: hs_code_us | G1: hs_code_uk | H1: hs_code_ca | I1: hs_code_eu | J1: hs_code_eu_sanction | K1: hs_code_au | L1: hs_code_dubai | M1: import_invoice_title
A2: AMZ-BAGF | B2: BAG-FOLD | C2: GRS Certified*** 100% Post Consumer Recycled Polyester (RM0189) | D2: Foldable Bag | E2: Bag - Foldable | F2: =_xlfn.IFNA(INDEX('HS Codes'!$D$2:$K2556,MATCH($B2,'HS Codes'!$A$2:$A2556,0),MATCH(F$1,'HS Codes'!$D$1:$K$1,0)),"") -> 4202.92.91.00 | G2: =_xlfn.IFNA(INDEX('HS Codes'!$D$2:$K2556,MATCH($B2,'HS Codes'!$A$2:$A2556,0),MATCH(G$1,'HS Codes'!$D$1:$K$1,0)),"") -> 4202921900 | H2: =_xlfn.IFNA(INDEX('HS Codes'!$D$2:$K2556,MATCH($B2,'HS Codes'!$A$2:$A2556,0),MATCH(H$1,'HS Codes'!$D$1:$K$1,0)),"") -> 4202.92.90.00 | I2: =_xlfn.IFNA(INDEX('HS Codes'!$D$2:$K2556,MATCH($B2,'HS Codes'!$A$2:$A2556,0),MATCH(I$1,'HS Codes'!$D$1:$K$1,0)),"") -> 4202 9298 90 | J2: =_xlfn.IFNA(INDEX('HS Codes'!$D$2:$K2556,MATCH($B2,'HS Codes'!$A$2:$A2556,0),MATCH(J$1,'HS Codes'!$D$1:$K$1,0)),"") -> 0 | K2: =_xlfn.IFNA(INDEX('HS Codes'!$D$2:$K2556,MATCH($B2,'HS Codes'!$A$2:$A2556,0),MATCH(K$1,'HS Codes'!$D$1:$K$1,0)),"") -> 4202.92.90 | L2: =_xlfn.IFNA(INDEX('HS Codes'!$D$2:$K2556,MATCH($B2,'HS Codes'!$A$2:$A2556,0),MATCH(L$1,'HS Codes'!$D$1:$K$1,0)),"") -> 42029100 | M2: =_xlfn.IFNA(INDEX('HS Codes'!$C$2:$C2556,MATCH($B2,'HS Codes'!$A$2:$A2556,0)),"") -> Shopping Bag 100% recycled polyester
A3: AMZ-DOGTWL | B3: DOGTWL | C3: GRS Certified* 83% Post Consumer Recycled Polyester (RM0189) 17% Pre Consumer Recycled Polyamide (RM1084) | D3: Towels - Dog | E3: Towel - Dog | F3: =_xlfn.IFNA(INDEX('HS Codes'!$D$2:$K2557,MATCH($B3,'HS Codes'!$A$2:$A2557,0),MATCH(F$1,'HS Codes'!$D$1:$K$1,0)),"") -> 6302.93.2000 | G3: =_xlfn.IFNA(INDEX('HS Codes'!$D$2:$K2557,MATCH($B3,'HS Codes'!$A$2:$A2557,0),MATCH(G$1,'HS Codes'!$D$1:$K$1,0)),"") -> 6302600090 | H3: =_xlfn.IFNA(INDEX('HS Codes'!$D$2:$K2557,MATCH($B3,'HS Codes'!$A$2:$A2557,0),MATCH(H$1,'HS Codes'!$D$1:$K$1,0)),"") -> 6302.93.00.00 | I3: =_xlfn.IFNA(INDEX('HS Codes'!$D$2:$K2557,MATCH($B3,'HS Codes'!$A$2:$A2557,0),MATCH(I$1,'HS Codes'!$D$1:$K$1,0)),"") -> 6302939000 | J3: =_xlfn.IFNA(INDEX('HS Codes'!$D$2:$K2557,MATCH($B3,'HS Codes'!$A$2:$A2557,0),MATCH(J$1,'HS Codes'!$D$1:$K$1,0)),"") -> 0 | K3: =_xlfn.IFNA(INDEX('HS Codes'!$D$2:$K2557,MATCH($B3,'HS Codes'!$A$2:$A2557,0),MATCH(K$1,'HS Codes'!$D$1:$K$1,0)),"") -> 6302.39.00 | L3: =_xlfn.IFNA(INDEX('HS Codes'!$D$2:$K2557,MATCH($B3,'HS Codes'!$A$2:$A2557,0),MATCH(L$1,'HS Codes'!$D$1:$K$1,0)),"") -> 6507 | M3: =_xlfn.IFNA(INDEX('HS Codes'!$C$2:$C2557,MATCH($B3,'HS Codes'!$A$2:$A2557,0)),"") -> Pet Towel - Toilet Linen 100% recycled 220 GSM/83% polyester/17% polyamide includes cotton on the packing pouch drawstring
A4: AMZ-PICNIC | B4: PICNIC | C4: GRS Certified** Upper: 83% Post Consumer Recycled Polyester (RM0189) 17% Pre Consumer Recycled Polyamide (RM1084) Reverse: 100% Post Consumer Recycled Polyester (RM0189) | D4: Picnic Blanket | E4: Picnic Blanket | F4: =_xlfn.IFNA(INDEX('HS Codes'!$D$2:$K2558,MATCH($B4,'HS Codes'!$A$2:$A2558,0),MATCH(F$1,'HS Codes'!$D$1:$K$1,0)),"") -> 6301.40.0020 | G4: =_xlfn.IFNA(INDEX('HS Codes'!$D$2:$K2558,MATCH($B4,'HS Codes'!$A$2:$A2558,0),MATCH(G$1,'HS Codes'!$D$1:$K$1,0)),"") -> 6301409099 | H4: =_xlfn.IFNA(INDEX('HS Codes'!$D$2:$K2558,MATCH($B4,'HS Codes'!$A$2:$A2558,0),MATCH(H$1,'HS Codes'!$D$1:$K$1,0)),"") -> 6301.40.0020 | I4: =_xlfn.IFNA(INDEX('HS Codes'!$D$2:$K2558,MATCH($B4,'HS Codes'!$A$2:$A2558,0),MATCH(I$1,'HS Codes'!$D$1:$K$1,0)),"") -> 6301409099 | J4: =_xlfn.IFNA(INDEX('HS Codes'!$D$2:$K2558,MATCH($B4,'HS Codes'!$A$2:$A2558,0),MATCH(J$1,'HS Codes'!$D$1:$K$1,0)),"") -> 0 | K4: =_xlfn.IFNA(INDEX('HS Codes'!$D$2:$K2558,MATCH($B4,'HS Codes'!$A$2:$A2558,0),MATCH(K$1,'HS Codes'!$D$1:$K$1,0)),"") -> 6301.40.00 | L4: =_xlfn.IFNA(INDEX('HS Codes'!$D$2:$K2558,MATCH($B4,'HS Codes'!$A$2:$A2558,0),MATCH(L$1,'HS Codes'!$D$1:$K$1,0)),"") -> 6301 | M4: =_xlfn.IFNA(INDEX('HS Codes'!$C$2:$C2558,MATCH($B4,'HS Codes'!$A$2:$A2558,0)),"") -> Travelling Rug 100% recycled. BOTTOM: 100% polyester. TOP: 220 GSM/83% polyester/17% polyamide includes cotton on the packing pouch drawstring
A5: AMZ-ROBE | B5: ROBE | D5: Bath Robe | E5: Bath Robe | F5: =_xlfn.IFNA(INDEX('HS Codes'!$D$2:$K2559,MATCH($B5,'HS Codes'!$A$2:$A2559,0),MATCH(F$1,'HS Codes'!$D$1:$K$1,0)),"") -> 6208.92.0010 | G5: =_xlfn.IFNA(INDEX('HS Codes'!$D$2:$K2559,MATCH($B5,'HS Codes'!$A$2:$A2559,0),MATCH(G$1,'HS Codes'!$D$1:$K$1,0)),"") -> 6208110000 | H5: =_xlfn.IFNA(INDEX('HS Codes'!$D$2:$K2559,MATCH($B5,'HS Codes'!$A$2:$A2559,0),MATCH(H$1,'HS Codes'!$D$1:$K$1,0)),"") -> 6208.92.00.00 | I5: =_xlfn.IFNA(INDEX('HS Codes'!$D$2:$K2559,MATCH($B5,'HS Codes'!$A$2:$A2559,0),MATCH(I$1,'HS Codes'!$D$1:$K$1,0)),"") -> 6208990099 | J5: =_xlfn.IFNA(INDEX('HS Codes'!$D$2:$K2559,MATCH($B5,'HS Codes'!$A$2:$A2559,0),MATCH(J$1,'HS Codes'!$D$1:$K$1,0)),"") -> 0 | K5: =_xlfn.IFNA(INDEX('HS Codes'!$D$2:$K2559,MATCH($B5,'HS Codes'!$A$2:$A2559,0),MATCH(K$1,'HS Codes'!$D$1:$K$1,0)),"") -> 6208.11.00 | L5: =_xlfn.IFNA(INDEX('HS Codes'!$D$2:$K2559,MATCH($B5,'HS Codes'!$A$2:$A2559,0),MATCH(L$1,'HS Codes'!$D$1:$K$1,0)),"") -> 62089200 | M5: =_xlfn.IFNA(INDEX('HS Codes'!$C$2:$C2559,MATCH($B5,'HS Codes'!$A$2:$A2559,0)),"") -> Bathrobe 100% recycled 220 GSM/83% polyester/17% polyamide includes cotton on the packing pouch drawstring
A6: BAGBCH-MD-NAVY | B6: BAG-BEACH | D6: Beach Bag | E6: Bag - Beach | F6: =_xlfn.IFNA(INDEX('HS Codes'!$D$2:$K2560,MATCH($B6,'HS Codes'!$A$2:$A2560,0),MATCH(F$1,'HS Codes'!$D$1:$K$1,0)),"") -> 4202.92.9100 | G6: =_xlfn.IFNA(INDEX('HS Codes'!$D$2:$K2560,MATCH($B6,'HS Codes'!$A$2:$A2560,0),MATCH(G$1,'HS Codes'!$D$1:$K$1,0)),"") -> 4202220000 | H6: =_xlfn.IFNA(INDEX('HS Codes'!$D$2:$K2560,MATCH($B6,'HS Codes'!$A$2:$A2560,0),MATCH(H$1,'HS Codes'!$D$1:$K$1,0)),"") -> 0 | I6: =_xlfn.IFNA(INDEX('HS Codes'!$D$2:$K2560,MATCH($B6,'HS Codes'!$A$2:$A2560,0),MATCH(I$1,'HS Codes'!$D$1:$K$1,0)),"") -> 42022290 | J6: =_xlfn.IFNA(INDEX('HS Codes'!$D$2:$K2560,MATCH($B6,'HS Codes'!$A$2:$A2560,0),MATCH(J$1,'HS Codes'!$D$1:$K$1,0)),"") -> 0 | K6: =_xlfn.IFNA(INDEX('HS Codes'!$D$2:$K2560,MATCH($B6,'HS Codes'!$A$2:$A2560,0),MATCH(K$1,'HS Codes'!$D$1:$K$1,0)),"") -> 4202.22.00 | L6: =_xlfn.IFNA(INDEX('HS Codes'!$D$2:$K2560,MATCH($B6,'HS Codes'!$A$2:$A2560,0),MATCH(L$1,'HS Codes'!$D$1:$K$1,0)),"") -> 42029100 | M6: =_xlfn.IFNA(INDEX('HS Codes'!$C$2:$C2560,MATCH($B6,'HS Codes'!$A$2:$A2560,0)),"") -> Beach Bag made from 100% polyester
A7: BAGBCH-MD-PSTPIER | B7: BAG-BEACH | D7: Beach Bag | E7: Bag - Beach | F7: =_xlfn.IFNA(INDEX('HS Codes'!$D$2:$K2561,MATCH($B7,'HS Codes'!$A$2:$A2561,0),MATCH(F$1,'HS Codes'!$D$1:$K$1,0)),"") -> 4202.92.9100 | G7: =_xlfn.IFNA(INDEX('HS Codes'!$D$2:$K2561,MATCH($B7,'HS Codes'!$A$2:$A2561,0),MATCH(G$1,'HS Codes'!$D$1:$K$1,0)),"") -> 4202220000 | H7: =_xlfn.IFNA(INDEX('HS Codes'!$D$2:$K2561,MATCH($B7,'HS Codes'!$A$2:$A2561,0),MATCH(H$1,'HS Codes'!$D$1:$K$1,0)),"") -> 0 | I7: =_xlfn.IFNA(INDEX('HS Codes'!$D$2:$K2561,MATCH($B7,'HS Codes'!$A$2:$A2561,0),MATCH(I$1,'HS Codes'!$D$1:$K$1,0)),"") -> 42022290 | J7: =_xlfn.IFNA(INDEX('HS Codes'!$D$2:$K2561,MATCH($B7,'HS Codes'!$A$2:$A2561,0),MATCH(J$1,'HS Codes'!$D$1:$K$1,0)),"") -> 0 | K7: =_xlfn.IFNA(INDEX('HS Codes'!$D$2:$K2561,MATCH($B7,'HS Codes'!$A$2:$A2561,0),MATCH(K$1,'HS Codes'!$D$1:$K$1,0)),"") -> 4202.22.00 | L7: =_xlfn.IFNA(INDEX('HS Codes'!$D$2:$K2561,MATCH($B7,'HS Codes'!$A$2:$A2561,0),MATCH(L$1,'HS Codes'!$D$1:$K$1,0)),"") -> 42029100 | M7: =_xlfn.IFNA(INDEX('HS Codes'!$C$2:$C2561,MATCH($B7,'HS Codes'!$A$2:$A2561,0)),"") -> Beach Bag made from 100% polyester
A8: BAGBCH-MD-RSPROAD | B8: BAG-BEACH | D8: Beach Bag | E8: Bag - Beach | F8: =_xlfn.IFNA(INDEX('HS Codes'!$D$2:$K2562,MATCH($B8,'HS Codes'!$A$2:$A2562,0),MATCH(F$1,'HS Codes'!$D$1:$K$1,0)),"") -> 4202.92.9100 | G8: =_xlfn.IFNA(INDEX('HS Codes'!$D$2:$K2562,MATCH($B8,'HS Codes'!$A$2:$A2562,0),MATCH(G$1,'HS Codes'!$D$1:$K$1,0)),"") -> 4202220000 | H8: =_xlfn.IFNA(INDEX('HS Codes'!$D$2:$K2562,MATCH($B8,'HS Codes'!$A$2:$A2562,0),MATCH(H$1,'HS Codes'!$D$1:$K$1,0)),"") -> 0 | I8: =_xlfn.IFNA(INDEX('HS Codes'!$D$2:$K2562,MATCH($B8,'HS Codes'!$A$2:$A2562,0),MATCH(I$1,'HS Codes'!$D$1:$K$1,0)),"") -> 42022290 | J8: =_xlfn.IFNA(INDEX('HS Codes'!$D$2:$K2562,MATCH($B8,'HS Codes'!$A$2:$A2562,0),MATCH(J$1,'HS Codes'!$D$1:$K$1,0)),"") -> 0 | K8: =_xlfn.IFNA(INDEX('HS Codes'!$D$2:$K2562,MATCH($B8,'HS Codes'!$A$2:$A2562,0),MATCH(K$1,'HS Codes'!$D$1:$K$1,0)),"") -> 4202.22.00 | L8: =_xlfn.IFNA(INDEX('HS Codes'!$D$2:$K2562,MATCH($B8,'HS Codes'!$A$2:$A2562,0),MATCH(L$1,'HS Codes'!$D$1:$K$1,0)),"") -> 42029100 | M8: =_xlfn.IFNA(INDEX('HS Codes'!$C$2:$C2562,MATCH($B8,'HS Codes'!$A$2:$A2562,0)),"") -> Beach Bag made from 100% polyester
A9: BAGCOOL-MD-APPLTRT | B9: BAG-COOL | D9: Cooling Bag | E9: Bag - Cooling | F9: =_xlfn.IFNA(INDEX('HS Codes'!$D$2:$K2563,MATCH($B9,'HS Codes'!$A$2:$A2563,0),MATCH(F$1,'HS Codes'!$D$1:$K$1,0)),"") -> 4202.92.9100 | G9: =_xlfn.IFNA(INDEX('HS Codes'!$D$2:$K2563,MATCH($B9,'HS Codes'!$A$2:$A2563,0),MATCH(G$1,'HS Codes'!$D$1:$K$1,0)),"") -> 4202220000 | H9: =_xlfn.IFNA(INDEX('HS Codes'!$D$2:$K2563,MATCH($B9,'HS Codes'!$A$2:$A2563,0),MATCH(H$1,'HS Codes'!$D$1:$K$1,0)),"") -> 0 | I9: =_xlfn.IFNA(INDEX('HS Codes'!$D$2:$K2563,MATCH($B9,'HS Codes'!$A$2:$A2563,0),MATCH(I$1,'HS Codes'!$D$1:$K$1,0)),"") -> 42022290 | J9: =_xlfn.IFNA(INDEX('HS Codes'!$D$2:$K2563,MATCH($B9,'HS Codes'!$A$2:$A2563,0),MATCH(J$1,'HS Codes'!$D$1:$K$1,0)),"") -> 0 | K9: =_xlfn.IFNA(INDEX('HS Codes'!$D$2:$K2563,MATCH($B9,'HS Codes'!$A$2:$A2563,0),MATCH(K$1,'HS Codes'!$D$1:$K$1,0)),"") -> 4202.22.00 | L9: =_xlfn.IFNA(INDEX('HS Codes'!$D$2:$K2563,MATCH($B9,'HS Codes'!$A$2:$A2563,0),MATCH(L$1,'HS Codes'!$D$1:$K$1,0)),"") -> 0 | M9: =_xlfn.IFNA(INDEX('HS Codes'!$C$2:$C2563,MATCH($B9,'HS Codes'!$A$2:$A2563,0)),"") -> Insulated Food or Beverage Bag Outer: 80% polyester, 20% PEVA
A10: BAGCOOL-MD-COLCLUB | B10: BAG-COOL | D10: Cooling Bag | E10: Bag - Cooling | F10: =_xlfn.IFNA(INDEX('HS Codes'!$D$2:$K2564,MATCH($B10,'HS Codes'!$A$2:$A2564,0),MATCH(F$1,'HS Codes'!$D$1:$K$1,0)),"") -> 4202.92.9100 | G10: =_xlfn.IFNA(INDEX('HS Codes'!$D$2:$K2564,MATCH($B10,'HS Codes'!$A$2:$A2564,0),MATCH(G$1,'HS Codes'!$D$1:$K$1,0)),"") -> 4202220000 | H10: =_xlfn.IFNA(INDEX('HS Codes'!$D$2:$K2564,MATCH($B10,'HS Codes'!$A$2:$A2564,0),MATCH(H$1,'HS Codes'!$D$1:$K$1,0)),"") -> 0 | I10: =_xlfn.IFNA(INDEX('HS Codes'!$D$2:$K2564,MATCH($B10,'HS Codes'!$A$2:$A2564,0),MATCH(I$1,'HS Codes'!$D$1:$K$1,0)),"") -> 42022290 | J10: =_xlfn.IFNA(INDEX('HS Codes'!$D$2:$K2564,MATCH($B10,'HS Codes'!$A$2:$A2564,0),MATCH(J$1,'HS Codes'!$D$1:$K$1,0)),"") -> 0 | K10: =_xlfn.IFNA(INDEX('HS Codes'!$D$2:$K2564,MATCH($B10,'HS Codes'!$A$2:$A2564,0),MATCH(K$1,'HS Codes'!$D$1:$K$1,0)),"") -> 4202.22.00 | L10: =_xlfn.IFNA(INDEX('HS Codes'!$D$2:$K2564,MATCH($B10,'HS Codes'!$A$2:$A2564,0),MATCH(L$1,'HS Codes'!$D$1:$K$1,0)),"") -> 0 | M10: =_xlfn.IFNA(INDEX('HS Codes'!$C$2:$C2564,MATCH($B10,'HS Codes'!$A$2:$A2564,0)),"") -> Insulated Food or Beverage Bag Outer: 80% polyester, 20% PEVA
A11: BAGCOOL-MD-NAVY | B11: BAG-COOL | D11: Cooling Bag | E11: Bag - Cooling | F11: =_xlfn.IFNA(INDEX('HS Codes'!$D$2:$K2565,MATCH($B11,'HS Codes'!$A$2:$A2565,0),MATCH(F$1,'HS Codes'!$D$1:$K$1,0)),"") -> 4202.92.9100 | G11: =_xlfn.IFNA(INDEX('HS Codes'!$D$2:$K2565,MATCH($B11,'HS Codes'!$A$2:$A2565,0),MATCH(G$1,'HS Codes'!$D$1:$K$1,0)),"") -> 4202220000 | H11: =_xlfn.IFNA(INDEX('HS Codes'!$D$2:$K2565,MATCH($B11,'HS Codes'!$A$2:$A2565,0),MATCH(H$1,'HS Codes'!$D$1:$K$1,0)),"") -> 0 | I11: =_xlfn.IFNA(INDEX('HS Codes'!$D$2:$K2565,MATCH($B11,'HS Codes'!$A$2:$A2565,0),MATCH(I$1,'HS Codes'!$D$1:$K$1,0)),"") -> 42022290 | J11: =_xlfn.IFNA(INDEX('HS Codes'!$D$2:$K2565,MATCH($B11,'HS Codes'!$A$2:$A2565,0),MATCH(J$1,'HS Codes'!$D$1:$K$1,0)),"") -> 0 | K11: =_xlfn.IFNA(INDEX('HS Codes'!$D$2:$K2565,MATCH($B11,'HS Codes'!$A$2:$A2565,0),MATCH(K$1,'HS Codes'!$D$1:$K$1,0)),"") -> 4202.22.00 | L11: =_xlfn.IFNA(INDEX('HS Codes'!$D$2:$K2565,MATCH($B11,'HS Codes'!$A$2:$A2565,0),MATCH(L$1,'HS Codes'!$D$1:$K$1,0)),"") -> 0 | M11: =_xlfn.IFNA(INDEX('HS Codes'!$C$2:$C2565,MATCH($B11,'HS Codes'!$A$2:$A2565,0)),"") -> Insulated Food or Beverage Bag Outer: 80% polyester, 20% PEVA
A12: BAGDRY-MD-IBZAGLW | B12: BAG-DRY-MD | D12: Dry Bag | E12: Bag - Dry | F12: =_xlfn.IFNA(INDEX('HS Codes'!$D$2:$K2566,MATCH($B12,'HS Codes'!$A$2:$A2566,0),MATCH(F$1,'HS Codes'!$D$1:$K$1,0)),"") -> 4202.92.9100 | G12: =_xlfn.IFNA(INDEX('HS Codes'!$D$2:$K2566,MATCH($B12,'HS Codes'!$A$2:$A2566,0),MATCH(G$1,'HS Codes'!$D$1:$K$1,0)),"") -> 4202220000 | H12: =_xlfn.IFNA(INDEX('HS Codes'!$D$2:$K2566,MATCH($B12,'HS Codes'!$A$2:$A2566,0),MATCH(H$1,'HS Codes'!$D$1:$K$1,0)),"") -> 0 | I12: =_xlfn.IFNA(INDEX('HS Codes'!$D$2:$K2566,MATCH($B12,'HS Codes'!$A$2:$A2566,0),MATCH(I$1,'HS Codes'!$D$1:$K$1,0)),"") -> 42022290 | J12: =_xlfn.IFNA(INDEX('HS Codes'!$D$2:$K2566,MATCH($B12,'HS Codes'!$A$2:$A2566,0),MATCH(J$1,'HS Codes'!$D$1:$K$1,0)),"") -> 0 | K12: =_xlfn.IFNA(INDEX('HS Codes'!$D$2:$K2566,MATCH($B12,'HS Codes'!$A$2:$A2566,0),MATCH(K$1,'HS Codes'!$D$1:$K$1,0)),"") -> 4202.22.00 | L12: =_xlfn.IFNA(INDEX('HS Codes'!$D$2:$K2566,MATCH($B12,'HS Codes'!$A$2:$A2566,0),MATCH(L$1,'HS Codes'!$D$1:$K$1,0)),"") -> 0 | M12: =_xlfn.IFNA(INDEX('HS Codes'!$C$2:$C2566,MATCH($B12,'HS Codes'!$A$2:$A2566,0)),"") -> Medium Dry Bag 80% TPU, 20% polyester
A13: BAGDRY-MD-MIAMI | B13: BAG-DRY-MD | D13: Dry Bag | E13: Bag - Dry | F13: =_xlfn.IFNA(INDEX('HS Codes'!$D$2:$K2567,MATCH($B13,'HS Codes'!$A$2:$A2567,0),MATCH(F$1,'HS Codes'!$D$1:$K$1,0)),"") -> 4202.92.9100 | G13: =_xlfn.IFNA(INDEX('HS Codes'!$D$2:$K2567,MATCH($B13,'HS Codes'!$A$2:$A2567,0),MATCH(G$1,'HS Codes'!$D$1:$K$1,0)),"") -> 4202220000 | H13: =_xlfn.IFNA(INDEX('HS Codes'!$D$2:$K2567,MATCH($B13,'HS Codes'!$A$2:$A2567,0),MATCH(H$1,'HS Codes'!$D$1:$K$1,0)),"") -> 0 | I13: =_xlfn.IFNA(INDEX('HS Codes'!$D$2:$K2567,MATCH($B13,'HS Codes'!$A$2:$A2567,0),MATCH(I$1,'HS Codes'!$D$1:$K$1,0)),"") -> 42022290 | J13: =_xlfn.IFNA(INDEX('HS Codes'!$D$2:$K2567,MATCH($B13,'HS Codes'!$A$2:$A2567,0),MATCH(J$1,'HS Codes'!$D$1:$K$1,0)),"") -> 0 | K13: =_xlfn.IFNA(INDEX('HS Codes'!$D$2:$K2567,MATCH($B13,'HS Codes'!$A$2:$A2567,0),MATCH(K$1,'HS Codes'!$D$1:$K$1,0)),"") -> 4202.22.00 | L13: =_xlfn.IFNA(INDEX('HS Codes'!$D$2:$K2567,MATCH($B13,'HS Codes'!$A$2:$A2567,0),MATCH(L$1,'HS Codes'!$D$1:$K$1,0)),"") -> 0 | M13: =_xlfn.IFNA(INDEX('HS Codes'!$C$2:$C2567,MATCH($B13,'HS Codes'!$A$2:$A2567,0)),"") -> Medium Dry Bag 80% TPU, 20% polyester
A14: BAGDRY-MD-NAVY | B14: BAG-DRY-MD | D14: Dry Bag | E14: Bag - Dry | F14: =_xlfn.IFNA(INDEX('HS Codes'!$D$2:$K2568,MATCH($B14,'HS Codes'!$A$2:$A2568,0),MATCH(F$1,'HS Codes'!$D$1:$K$1,0)),"") -> 4202.92.9100 | G14: =_xlfn.IFNA(INDEX('HS Codes'!$D$2:$K2568,MATCH($B14,'HS Codes'!$A$2:$A2568,0),MATCH(G$1,'HS Codes'!$D$1:$K$1,0)),"") -> 4202220000 | H14: =_xlfn.IFNA(INDEX('HS Codes'!$D$2:$K2568,MATCH($B14,'HS Codes'!$A$2:$A2568,0),MATCH(H$1,'HS Codes'!$D$1:$K$1,0)),"") -> 0 | I14: =_xlfn.IFNA(INDEX('HS Codes'!$D$2:$K2568,MATCH($B14,'HS Codes'!$A$2:$A2568,0),MATCH(I$1,'HS Codes'!$D$1:$K$1,0)),"") -> 42022290 | J14: =_xlfn.IFNA(INDEX('HS Codes'!$D$2:$K2568,MATCH($B14,'HS Codes'!$A$2:$A2568,0),MATCH(J$1,'HS Codes'!$D$1:$K$1,0)),"") -> 0 | K14: =_xlfn.IFNA(INDEX('HS Codes'!$D$2:$K2568,MATCH($B14,'HS Codes'!$A$2:$A2568,0),MATCH(K$1,'HS Codes'!$D$1:$K$1,0)),"") -> 4202.22.00 | L14: =_xlfn.IFNA(INDEX('HS Codes'!$D$2:$K2568,MATCH($B14,'HS Codes'!$A$2:$A2568,0),MATCH(L$1,'HS Codes'!$D$1:$K$1,0)),"") -> 0 | M14: =_xlfn.IFNA(INDEX('HS Codes'!$C$2:$C2568,MATCH($B14,'HS Codes'!$A$2:$A2568,0)),"") -> Medium Dry Bag 80% TPU, 20% polyester
A15: BAGDRY-MD-WAVYBBY | B15: BAG-DRY-MD | D15: Dry Bag | E15: Bag - Dry | F15: =_xlfn.IFNA(INDEX('HS Codes'!$D$2:$K2569,MATCH($B15,'HS Codes'!$A$2:$A2569,0),MATCH(F$1,'HS Codes'!$D$1:$K$1,0)),"") -> 4202.92.9100 | G15: =_xlfn.IFNA(INDEX('HS Codes'!$D$2:$K2569,MATCH($B15,'HS Codes'!$A$2:$A2569,0),MATCH(G$1,'HS Codes'!$D$1:$K$1,0)),"") -> 4202220000 | H15: =_xlfn.IFNA(INDEX('HS Codes'!$D$2:$K2569,MATCH($B15,'HS Codes'!$A$2:$A2569,0),MATCH(H$1,'HS Codes'!$D$1:$K$1,0)),"") -> 0 | I15: =_xlfn.IFNA(INDEX('HS Codes'!$D$2:$K2569,MATCH($B15,'HS Codes'!$A$2:$A2569,0),MATCH(I$1,'HS Codes'!$D$1:$K$1,0)),"") -> 42022290 | J15: =_xlfn.IFNA(INDEX('HS Codes'!$D$2:$K2569,MATCH($B15,'HS Codes'!$A$2:$A2569,0),MATCH(J$1,'HS Codes'!$D$1:$K$1,0)),"") -> 0 | K15: =_xlfn.IFNA(INDEX('HS Codes'!$D$2:$K2569,MATCH($B15,'HS Codes'!$A$2:$A2569,0),MATCH(K$1,'HS Codes'!$D$1:$K$1,0)),"") -> 4202.22.00 | L15: =_xlfn.IFNA(INDEX('HS Codes'!$D$2:$K2569,MATCH($B15,'HS Codes'!$A$2:$A2569,0),MATCH(L$1,'HS Codes'!$D$1:$K$1,0)),"") -> 0 | M15: =_xlfn.IFNA(INDEX('HS Codes'!$C$2:$C2569,MATCH($B15,'HS Codes'!$A$2:$A2569,0)),"") -> Medium Dry Bag 80% TPU, 20% polyester
A16: BAGDRY-XS-HOTTROP | B16: BAG-DRY-SM | D16: Dry Bag | E16: Bag - Dry | F16: =_xlfn.IFNA(INDEX('HS Codes'!$D$2:$K2570,MATCH($B16,'HS Codes'!$A$2:$A2570,0),MATCH(F$1,'HS Codes'!$D$1:$K$1,0)),"") -> 4202.92.9100 | G16: =_xlfn.IFNA(INDEX('HS Codes'!$D$2:$K2570,MATCH($B16,'HS Codes'!$A$2:$A2570,0),MATCH(G$1,'HS Codes'!$D$1:$K$1,0)),"") -> 4202220000 | H16: =_xlfn.IFNA(INDEX('HS Codes'!$D$2:$K2570,MATCH($B16,'HS Codes'!$A$2:$A2570,0),MATCH(H$1,'HS Codes'!$D$1:$K$1,0)),"") -> 0 | I16: =_xlfn.IFNA(INDEX('HS Codes'!$D$2:$K2570,MATCH($B16,'HS Codes'!$A$2:$A2570,0),MATCH(I$1,'HS Codes'!$D$1:$K$1,0)),"") -> 42022290 | J16: =_xlfn.IFNA(INDEX('HS Codes'!$D$2:$K2570,MATCH($B16,'HS Codes'!$A$2:$A2570,0),MATCH(J$1,'HS Codes'!$D$1:$K$1,0)),"") -> 0 | K16: =_xlfn.IFNA(INDEX('HS Codes'!$D$2:$K2570,MATCH($B16,'HS Codes'!$A$2:$A2570,0),MATCH(K$1,'HS Codes'!$D$1:$K$1,0)),"") -> 4202.22.00 | L16: =_xlfn.IFNA(INDEX('HS Codes'!$D$2:$K2570,MATCH($B16,'HS Codes'!$A$2:$A2570,0),MATCH(L$1,'HS Codes'!$D$1:$K$1,0)),"") -> 0 | M16: =_xlfn.IFNA(INDEX('HS Codes'!$C$2:$C2570,MATCH($B16,'HS Codes'!$A$2:$A2570,0)),"") -> Small Dry Bag 80% polyester, 20% polyurethane (PU)
... A20: BAGDRY-XS-WYWH | B20: BAG-DRY-SM | D20: Dry Bag | E20: Bag - Dry | F20: =_xlfn.IFNA(INDEX('HS Codes'!$D$2:$K2574,MATCH($B20,'HS Codes'!$A$2:$A2574,0),MATCH(F$1,'HS Codes'!$D$1:$K$1,0)),"") -> 4202.92.9100 | G20: =_xlfn.IFNA(INDEX('HS Codes'!$D$2:$K2574,MATCH($B20,'HS Codes'!$A$2:$A2574,0),MATCH(G$1,'HS Codes'!$D$1:$K$1,0)),"") -> 4202220000 | H20: =_xlfn.IFNA(INDEX('HS Codes'!$D$2:$K2574,MATCH($B20,'HS Codes'!$A$2:$A2574,0),MATCH(H$1,'HS Codes'!$D$1:$K$1,0)),"") -> 0 | I20: =_xlfn.IFNA(INDEX('HS Codes'!$D$2:$K2574,MATCH($B20,'HS Codes'!$A$2:$A2574,0),MATCH(I$1,'HS Codes'!$D$1:$K$1,0)),"") -> 42022290 | J20: =_xlfn.IFNA(INDEX('HS Codes'!$D$2:$K2574,MATCH($B20,'HS Codes'!$A$2:$A2574,0),MATCH(J$1,'HS Codes'!$D$1:$K$1,0)),"") -> 0 | K20: =_xlfn.IFNA(INDEX('HS Codes'!$D$2:$K2574,MATCH($B20,'HS Codes'!$A$2:$A2574,0),MATCH(K$1,'HS Codes'!$D$1:$K$1,0)),"") -> 4202.22.00 | L20: =_xlfn.IFNA(INDEX('HS Codes'!$D$2:$K2574,MATCH($B20,'HS Codes'!$A$2:$A2574,0),MATCH(L$1,'HS Codes'!$D$1:$K$1,0)),"") -> 0 | M20: =_xlfn.IFNA(INDEX('HS Codes'!$C$2:$C2574,MATCH($B20,'HS Codes'!$A$2:$A2574,0)),"") -> Small Dry Bag 80% polyester, 20% polyurethane (PU)
A21: BAGF-CAB-MD-LTPNK | B21: BAG-FOLD | C21: GRS Certified*** 100% Post Consumer Recycled Polyester (RM0189) | D21: Foldable Bag | E21: Bag - Foldable | F21: =_xlfn.IFNA(INDEX('HS Codes'!$D$2:$K2575,MATCH($B21,'HS Codes'!$A$2:$A2575,0),MATCH(F$1,'HS Codes'!$D$1:$K$1,0)),"") -> 4202.92.91.00 | G21: =_xlfn.IFNA(INDEX('HS Codes'!$D$2:$K2575,MATCH($B21,'HS Codes'!$A$2:$A2575,0),MATCH(G$1,'HS Codes'!$D$1:$K$1,0)),"") -> 4202921900 | H21: =_xlfn.IFNA(INDEX('HS Codes'!$D$2:$K2575,MATCH($B21,'HS Codes'!$A$2:$A2575,0),MATCH(H$1,'HS Codes'!$D$1:$K$1,0)),"") -> 4202.92.90.00 | I21: =_xlfn.IFNA(INDEX('HS Codes'!$D$2:$K2575,MATCH($B21,'HS Codes'!$A$2:$A2575,0),MATCH(I$1,'HS Codes'!$D$1:$K$1,0)),"") -> 4202 9298 90 | J21: =_xlfn.IFNA(INDEX('HS Codes'!$D$2:$K2575,MATCH($B21,'HS Codes'!$A$2:$A2575,0),MATCH(J$1,'HS Codes'!$D$1:$K$1,0)),"") -> 0 | K21: =_xlfn.IFNA(INDEX('HS Codes'!$D$2:$K2575,MATCH($B21,'HS Codes'!$A$2:$A2575,0),MATCH(K$1,'HS Codes'!$D$1:$K$1,0)),"") -> 4202.92.90 | L21: =_xlfn.IFNA(INDEX('HS Codes'!$D$2:$K2575,MATCH($B21,'HS Codes'!$A$2:$A2575,0),MATCH(L$1,'HS Codes'!$D$1:$K$1,0)),"") -> 42029100 | M21: =_xlfn.IFNA(INDEX('HS Codes'!$C$2:$C2575,MATCH($B21,'HS Codes'!$A$2:$A2575,0)),"") -> Shopping Bag 100% recycled polyester
A22: BAGF-CAB-MD-NAVY | B22: BAG-FOLD | C22: GRS Certified*** 100% Post Consumer Recycled Polyester (RM0189) | D22: Foldable Bag | E22: Bag - Foldable | F22: =_xlfn.IFNA(INDEX('HS Codes'!$D$2:$K2576,MATCH($B22,'HS Codes'!$A$2:$A2576,0),MATCH(F$1,'HS Codes'!$D$1:$K$1,0)),"") -> 4202.92.91.00 | G22: =_xlfn.IFNA(INDEX('HS Codes'!$D$2:$K2576,MATCH($B22,'HS Codes'!$A$2:$A2576,0),MATCH(G$1,'HS Codes'!$D$1:$K$1,0)),"") -> 4202921900 | H22: =_xlfn.IFNA(INDEX('HS Codes'!$D$2:$K2576,MATCH($B22,'HS Codes'!$A$2:$A2576,0),MATCH(H$1,'HS Codes'!$D$1:$K$1,0)),"") -> 4202.92.90.00 | I22: =_xlfn.IFNA(INDEX('HS Codes'!$D$2:$K2576,MATCH($B22,'HS Codes'!$A$2:$A2576,0),MATCH(I$1,'HS Codes'!$D$1:$K$1,0)),"") -> 4202 9298 90 | J22: =_xlfn.IFNA(INDEX('HS Codes'!$D$2:$K2576,MATCH($B22,'HS Codes'!$A$2:$A2576,0),MATCH(J$1,'HS Codes'!$D$1:$K$1,0)),"") -> 0 | K22: =_xlfn.IFNA(INDEX('HS Codes'!$D$2:$K2576,MATCH($B22,'HS Codes'!$A$2:$A2576,0),MATCH(K$1,'HS Codes'!$D$1:$K$1,0)),"") -> 4202.92.90 | L22: =_xlfn.IFNA(INDEX('HS Codes'!$D$2:$K2576,MATCH($B22,'HS Codes'!$A$2:$A2576,0),MATCH(L$1,'HS Codes'!$D$1:$K$1,0)),"") -> 42029100 | M22: =_xlfn.IFNA(INDEX('HS Codes'!$C$2:$C2576,MATCH($B22,'HS Codes'!$A$2:$A2576,0)),"") -> Shopping Bag 100% recycled polyester
A23: BAGF-DES-MD-IBZAGLW | B23: BAG-FOLD | C23: GRS Certified*** 100% Post Consumer Recycled Polyester (RM0189) | D23: Foldable Bag | E23: Bag - Foldable | F23: =_xlfn.IFNA(INDEX('HS Codes'!$D$2:$K2577,MATCH($B23,'HS Codes'!$A$2:$A2577,0),MATCH(F$1,'HS Codes'!$D$1:$K$1,0)),"") -> 4202.92.91.00 | G23: =_xlfn.IFNA(INDEX('HS Codes'!$D$2:$K2577,MATCH($B23,'HS Codes'!$A$2:$A2577,0),MATCH(G$1,'HS Codes'!$D$1:$K$1,0)),"") -> 4202921900 | H23: =_xlfn.IFNA(INDEX('HS Codes'!$D$2:$K2577,MATCH($B23,'HS Codes'!$A$2:$A2577,0),MATCH(H$1,'HS Codes'!$D$1:$K$1,0)),"") -> 4202.92.90.00 | I23: =_xlfn.IFNA(INDEX('HS Codes'!$D$2:$K2577,MATCH($B23,'HS Codes'!$A$2:$A2577,0),MATCH(I$1,'HS Codes'!$D$1:$K$1,0)),"") -> 4202 9298 90 | J23: =_xlfn.IFNA(INDEX('HS Codes'!$D$2:$K2577,MATCH($B23,'HS Codes'!$A$2:$A2577,0),MATCH(J$1,'HS Codes'!$D$1:$K$1,0)),"") -> 0 | K23: =_xlfn.IFNA(INDEX('HS Codes'!$D$2:$K2577,MATCH($B23,'HS Codes'!$A$2:$A2577,0),MATCH(K$1,'HS Codes'!$D$1:$K$1,0)),"") -> 4202.92.90 | L23: =_xlfn.IFNA(INDEX('HS Codes'!$D$2:$K2577,MATCH($B23,'HS Codes'!$A$2:$A2577,0),MATCH(L$1,'HS Codes'!$D$1:$K$1,0)),"") -> 42029100 | M23: =_xlfn.IFNA(INDEX('HS Codes'!$C$2:$C2577,MATCH($B23,'HS Codes'!$A$2:$A2577,0)),"") -> Shopping Bag 100% recycled polyester
A24: BAGF-DES-MD-SPRCLUB | B24: BAG-FOLD | C24: GRS Certified*** 100% Post Consumer Recycled Polyester (RM0189) | D24: Foldable Bag | E24: Bag - Foldable | F24: =_xlfn.IFNA(INDEX('HS Codes'!$D$2:$K2578,MATCH($B24,'HS Codes'!$A$2:$A2578,0),MATCH(F$1,'HS Codes'!$D$1:$K$1,0)),"") -> 4202.92.91.00 | G24: =_xlfn.IFNA(INDEX('HS Codes'!$D$2:$K2578,MATCH($B24,'HS Codes'!$A$2:$A2578,0),MATCH(G$1,'HS Codes'!$D$1:$K$1,0)),"") -> 4202921900 | H24: =_xlfn.IFNA(INDEX('HS Codes'!$D$2:$K2578,MATCH($B24,'HS Codes'!$A$2:$A2578,0),MATCH(H$1,'HS Codes'!$D$1:$K$1,0)),"") -> 4202.92.90.00 | I24: =_xlfn.IFNA(INDEX('HS Codes'!$D$2:$K2578,MATCH($B24,'HS Codes'!$A$2:$A2578,0),MATCH(I$1,'HS Codes'!$D$1:$K$1,0)),"") -> 4202 9298 90 | J24: =_xlfn.IFNA(INDEX('HS Codes'!$D$2:$K2578,MATCH($B24,'HS Codes'!$A$2:$A2578,0),MATCH(J$1,'HS Codes'!$D$1:$K$1,0)),"") -> 0 | K24: =_xlfn.IFNA(INDEX('HS Codes'!$D$2:$K2578,MATCH($B24,'HS Codes'!$A$2:$A2578,0),MATCH(K$1,'HS Codes'!$D$1:$K$1,0)),"") -> 4202.92.90 | L24: =_xlfn.IFNA(INDEX('HS Codes'!$D$2:$K2578,MATCH($B24,'HS Codes'!$A$2:$A2578,0),MATCH(L$1,'HS Codes'!$D$1:$K$1,0)),"") -> 42029100 | M24: =_xlfn.IFNA(INDEX('HS Codes'!$C$2:$C2578,MATCH($B24,'HS Codes'!$A$2:$A2578,0)),"") -> Shopping Bag 100% recycled polyester
A25: BAGF-DES-MD-WAVYBBY | B25: BAG-FOLD | C25: GRS Certified*** 100% Post Consumer Recycled Polyester (RM0189) | D25: Foldable Bag | E25: Bag - Foldable | F25: =_xlfn.IFNA(INDEX('HS Codes'!$D$2:$K2579,MATCH($B25,'HS Codes'!$A$2:$A2579,0),MATCH(F$1,'HS Codes'!$D$1:$K$1,0)),"") -> 4202.92.91.00 | G25: =_xlfn.IFNA(INDEX('HS Codes'!$D$2:$K2579,MATCH($B25,'HS Codes'!$A$2:$A2579,0),MATCH(G$1,'HS Codes'!$D$1:$K$1,0)),"") -> 4202921900 | H25: =_xlfn.IFNA(INDEX('HS Codes'!$D$2:$K2579,MATCH($B25,'HS Codes'!$A$2:$A2579,0),MATCH(H$1,'HS Codes'!$D$1:$K$1,0)),"") -> 4202.92.90.00 | I25: =_xlfn.IFNA(INDEX('HS Codes'!$D$2:$K2579,MATCH($B25,'HS Codes'!$A$2:$A2579,0),MATCH(I$1,'HS Codes'!$D$1:$K$1,0)),"") -> 4202 9298 90 | J25: =_xlfn.IFNA(INDEX('HS Codes'!$D$2:$K2579,MATCH($B25,'HS Codes'!$A$2:$A2579,0),MATCH(J$1,'HS Codes'!$D$1:$K$1,0)),"") -> 0 | K25: =_xlfn.IFNA(INDEX('HS Codes'!$D$2:$K2579,MATCH($B25,'HS Codes'!$A$2:$A2579,0),MATCH(K$1,'HS Codes'!$D$1:$K$1,0)),"") -> 4202.92.90 | L25: =_xlfn.IFNA(INDEX('HS Codes'!$D$2:$K2579,MATCH($B25,'HS Codes'!$A$2:$A2579,0),MATCH(L$1,'HS Codes'!$D$1:$K$1,0)),"") -> 42029100 | M25: =_xlfn.IFNA(INDEX('HS Codes'!$C$2:$C2579,MATCH($B25,'HS Codes'!$A$2:$A2579,0)),"") -> Shopping Bag 100% recycled polyester
A26: BAGF-DES-MD-WTRSUG | B26: BAG-FOLD | C26: GRS Certified*** 100% Post Consumer Recycled Polyester (RM0189) | D26: Foldable Bag | E26: Bag - Foldable | F26: =_xlfn.IFNA(INDEX('HS Codes'!$D$2:$K2580,MATCH($B26,'HS Codes'!$A$2:$A2580,0),MATCH(F$1,'HS Codes'!$D$1:$K$1,0)),"") -> 4202.92.91.00 | G26: =_xlfn.IFNA(INDEX('HS Codes'!$D$2:$K2580,MATCH($B26,'HS Codes'!$A$2:$A2580,0),MATCH(G$1,'HS Codes'!$D$1:$K$1,0)),"") -> 4202921900 | H26: =_xlfn.IFNA(INDEX('HS Codes'!$D$2:$K2580,MATCH($B26,'HS Codes'!$A$2:$A2580,0),MATCH(H$1,'HS Codes'!$D$1:$K$1,0)),"") -> 4202.92.90.00 | I26: =_xlfn.IFNA(INDEX('HS Codes'!$D$2:$K2580,MATCH($B26,'HS Codes'!$A$2:$A2580,0),MATCH(I$1,'HS Codes'!$D$1:$K$1,0)),"") -> 4202 9298 90 | J26: =_xlfn.IFNA(INDEX('HS Codes'!$D$2:$K2580,MATCH($B26,'HS Codes'!$A$2:$A2580,0),MATCH(J$1,'HS Codes'!$D$1:$K$1,0)),"") -> 0 | K26: =_xlfn.IFNA(INDEX('HS Codes'!$D$2:$K2580,MATCH($B26,'HS Codes'!$A$2:$A2580,0),MATCH(K$1,'HS Codes'!$D$1:$K$1,0)),"") -> 4202.92.90 | L26: =_xlfn.IFNA(INDEX('HS Codes'!$D$2:$K2580,MATCH($B26,'HS Codes'!$A$2:$A2580,0),MATCH(L$1,'HS Codes'!$D$1:$K$1,0)),"") -> 42029100 | M26: =_xlfn.IFNA(INDEX('HS Codes'!$C$2:$C2580,MATCH($B26,'HS Codes'!$A$2:$A2580,0)),"") -> Shopping Bag 100% recycled polyester
A27: BAGF-DES-MD-WYWH | B27: BAG-FOLD | C27: GRS Certified*** 100% Post Consumer Recycled Polyester (RM0189) | D27: Foldable Bag | E27: Bag - Foldable | F27: =_xlfn.IFNA(INDEX('HS Codes'!$D$2:$K2581,MATCH($B27,'HS Codes'!$A$2:$A2581,0),MATCH(F$1,'HS Codes'!$D$1:$K$1,0)),"") -> 4202.92.91.00 | G27: =_xlfn.IFNA(INDEX('HS Codes'!$D$2:$K2581,MATCH($B27,'HS Codes'!$A$2:$A2581,0),MATCH(G$1,'HS Codes'!$D$1:$K$1,0)),"") -> 4202921900 | H27: =_xlfn.IFNA(INDEX('HS Codes'!$D$2:$K2581,MATCH($B27,'HS Codes'!$A$2:$A2581,0),MATCH(H$1,'HS Codes'!$D$1:$K$1,0)),"") -> 4202.92.90.00 | I27: =_xlfn.IFNA(INDEX('HS Codes'!$D$2:$K2581,MATCH($B27,'HS Codes'!$A$2:$A2581,0),MATCH(I$1,'HS Codes'!$D$1:$K$1,0)),"") -> 4202 9298 90 | J27: =_xlfn.IFNA(INDEX('HS Codes'!$D$2:$K2581,MATCH($B27,'HS Codes'!$A$2:$A2581,0),MATCH(J$1,'HS Codes'!$D$1:$K$1,0)),"") -> 0 | K27: =_xlfn.IFNA(INDEX('HS Codes'!$D$2:$K2581,MATCH($B27,'HS Codes'!$A$2:$A2581,0),MATCH(K$1,'HS Codes'!$D$1:$K$1,0)),"") -> 4202.92.90 | L27: =_xlfn.IFNA(INDEX('HS Codes'!$D$2:$K2581,MATCH($B27,'HS Codes'!$A$2:$A2581,0),MATCH(L$1,'HS Codes'!$D$1:$K$1,0)),"") -> 42029100 | M27: =_xlfn.IFNA(INDEX('HS Codes'!$C$2:$C2581,MATCH($B27,'HS Codes'!$A$2:$A2581,0)),"") -> Shopping Bag 100% recycled polyester
A28: BAGF-SUM-MD-COLAGN | B28: BAG-FOLD | C28: GRS Certified*** 100% Post Consumer Recycled Polyester (RM0189) | D28: Foldable Bag | E28: Bag - Foldable | F28: =_xlfn.IFNA(INDEX('HS Codes'!$D$2:$K2582,MATCH($B28,'HS Codes'!$A$2:$A2582,0),MATCH(F$1,'HS Codes'!$D$1:$K$1,0)),"") -> 4202.92.91.00 | G28: =_xlfn.IFNA(INDEX('HS Codes'!$D$2:$K2582,MATCH($B28,'HS Codes'!$A$2:$A2582,0),MATCH(G$1,'HS Codes'!$D$1:$K$1,0)),"") -> 4202921900 | H28: =_xlfn.IFNA(INDEX('HS Codes'!$D$2:$K2582,MATCH($B28,'HS Codes'!$A$2:$A2582,0),MATCH(H$1,'HS Codes'!$D$1:$K$1,0)),"") -> 4202.92.90.00 | I28: =_xlfn.IFNA(INDEX('HS Codes'!$D$2:$K2582,MATCH($B28,'HS Codes'!$A$2:$A2582,0),MATCH(I$1,'HS Codes'!$D$1:$K$1,0)),"") -> 4202 9298 90 | J28: =_xlfn.IFNA(INDEX('HS Codes'!$D$2:$K2582,MATCH($B28,'HS Codes'!$A$2:$A2582,0),MATCH(J$1,'HS Codes'!$D$1:$K$1,0)),"") -> 0 | K28: =_xlfn.IFNA(INDEX('HS Codes'!$D$2:$K2582,MATCH($B28,'HS Codes'!$A$2:$A2582,0),MATCH(K$1,'HS Codes'!$D$1:$K$1,0)),"") -> 4202.92.90 | L28: =_xlfn.IFNA(INDEX('HS Codes'!$D$2:$K2582,MATCH($B28,'HS Codes'!$A$2:$A2582,0),MATCH(L$1,'HS Codes'!$D$1:$K$1,0)),"") -> 42029100 | M28: =_xlfn.IFNA(INDEX('HS Codes'!$C$2:$C2582,MATCH($B28,'HS Codes'!$A$2:$A2582,0)),"") -> Shopping Bag 100% recycled polyester
A29: BAGF-SUM-MD-CSTCANDY | B29: BAG-FOLD | C29: GRS Certified*** 100% Post Consumer Recycled Polyester (RM0189) | D29: Foldable Bag | E29: Bag - Foldable | F29: =_xlfn.IFNA(INDEX('HS Codes'!$D$2:$K2583,MATCH($B29,'HS Codes'!$A$2:$A2583,0),MATCH(F$1,'HS Codes'!$D$1:$K$1,0)),"") -> 4202.92.91.00 | G29: =_xlfn.IFNA(INDEX('HS Codes'!$D$2:$K2583,MATCH($B29,'HS Codes'!$A$2:$A2583,0),MATCH(G$1,'HS Codes'!$D$1:$K$1,0)),"") -> 4202921900 | H29: =_xlfn.IFNA(INDEX('HS Codes'!$D$2:$K2583,MATCH($B29,'HS Codes'!$A$2:$A2583,0),MATCH(H$1,'HS Codes'!$D$1:$K$1,0)),"") -> 4202.92.90.00 | I29: =_xlfn.IFNA(INDEX('HS Codes'!$D$2:$K2583,MATCH($B29,'HS Codes'!$A$2:$A2583,0),MATCH(I$1,'HS Codes'!$D$1:$K$1,0)),"") -> 4202 9298 90 | J29: =_xlfn.IFNA(INDEX('HS Codes'!$D$2:$K2583,MATCH($B29,'HS Codes'!$A$2:$A2583,0),MATCH(J$1,'HS Codes'!$D$1:$K$1,0)),"") -> 0 | K29: =_xlfn.IFNA(INDEX('HS Codes'!$D$2:$K2583,MATCH($B29,'HS Codes'!$A$2:$A2583,0),MATCH(K$1,'HS Codes'!$D$1:$K$1,0)),"") -> 4202.92.90 | L29: =_xlfn.IFNA(INDEX('HS Codes'!$D$2:$K2583,MATCH($B29,'HS Codes'!$A$2:$A2583,0),MATCH(L$1,'HS Codes'!$D$1:$K$1,0)),"") -> 42029100 | M29: =_xlfn.IFNA(INDEX('HS Codes'!$C$2:$C2583,MATCH($B29,'HS Codes'!$A$2:$A2583,0)),"") -> Shopping Bag 100% recycled polyester
A30: BAGF-SUM-MD-MIAMI | B30: BAG-FOLD | C30: GRS Certified*** 100% Post Consumer Recycled Polyester (RM0189) | D30: Foldable Bag | E30: Bag - Foldable | F30: =_xlfn.IFNA(INDEX('HS Codes'!$D$2:$K2584,MATCH($B30,'HS Codes'!$A$2:$A2584,0),MATCH(F$1,'HS Codes'!$D$1:$K$1,0)),"") -> 4202.92.91.00 | G30: =_xlfn.IFNA(INDEX('HS Codes'!$D$2:$K2584,MATCH($B30,'HS Codes'!$A$2:$A2584,0),MATCH(G$1,'HS Codes'!$D$1:$K$1,0)),"") -> 4202921900 | H30: =_xlfn.IFNA(INDEX('HS Codes'!$D$2:$K2584,MATCH($B30,'HS Codes'!$A$2:$A2584,0),MATCH(H$1,'HS Codes'!$D$1:$K$1,0)),"") -> 4202.92.90.00 | I30: =_xlfn.IFNA(INDEX('HS Codes'!$D$2:$K2584,MATCH($B30,'HS Codes'!$A$2:$A2584,0),MATCH(I$1,'HS Codes'!$D$1:$K$1,0)),"") -> 4202 9298 90 | J30: =_xlfn.IFNA(INDEX('HS Codes'!$D$2:$K2584,MATCH($B30,'HS Codes'!$A$2:$A2584,0),MATCH(J$1,'HS Codes'!$D$1:$K$1,0)),"") -> 0 | K30: =_xlfn.IFNA(INDEX('HS Codes'!$D$2:$K2584,MATCH($B30,'HS Codes'!$A$2:$A2584,0),MATCH(K$1,'HS Codes'!$D$1:$K$1,0)),"") -> 4202.92.90 | L30: =_xlfn.IFNA(INDEX('HS Codes'!$D$2:$K2584,MATCH($B30,'HS Codes'!$A$2:$A2584,0),MATCH(L$1,'HS Codes'!$D$1:$K$1,0)),"") -> 42029100 | M30: =_xlfn.IFNA(INDEX('HS Codes'!$C$2:$C2584,MATCH($B30,'HS Codes'!$A$2:$A2584,0)),"") -> Shopping Bag 100% recycled polyester
A31: BAGF-SUM-MD-UNICN | B31: BAG-FOLD | C31: GRS Certified*** 100% Post Consumer Recycled Polyester (RM0189) | D31: Foldable Bag | E31: Bag - Foldable | F31: =_xlfn.IFNA(INDEX('HS Codes'!$D$2:$K2585,MATCH($B31,'HS Codes'!$A$2:$A2585,0),MATCH(F$1,'HS Codes'!$D$1:$K$1,0)),"") -> 4202.92.91.00 | G31: =_xlfn.IFNA(INDEX('HS Codes'!$D$2:$K2585,MATCH($B31,'HS Codes'!$A$2:$A2585,0),MATCH(G$1,'HS Codes'!$D$1:$K$1,0)),"") -> 4202921900 | H31: =_xlfn.IFNA(INDEX('HS Codes'!$D$2:$K2585,MATCH($B31,'HS Codes'!$A$2:$A2585,0),MATCH(H$1,'HS Codes'!$D$1:$K$1,0)),"") -> 4202.92.90.00 | I31: =_xlfn.IFNA(INDEX('HS Codes'!$D$2:$K2585,MATCH($B31,'HS Codes'!$A$2:$A2585,0),MATCH(I$1,'HS Codes'!$D$1:$K$1,0)),"") -> 4202 9298 90 | J31: =_xlfn.IFNA(INDEX('HS Codes'!$D$2:$K2585,MATCH($B31,'HS Codes'!$A$2:$A2585,0),MATCH(J$1,'HS Codes'!$D$1:$K$1,0)),"") -> 0 | K31: =_xlfn.IFNA(INDEX('HS Codes'!$D$2:$K2585,MATCH($B31,'HS Codes'!$A$2:$A2585,0),MATCH(K$1,'HS Codes'!$D$1:$K$1,0)),"") -> 4202.92.90 | L31: =_xlfn.IFNA(INDEX('HS Codes'!$D$2:$K2585,MATCH($B31,'HS Codes'!$A$2:$A2585,0),MATCH(L$1,'HS Codes'!$D$1:$K$1,0)),"") -> 42029100 | M31: =_xlfn.IFNA(INDEX('HS Codes'!$C$2:$C2585,MATCH($B31,'HS Codes'!$A$2:$A2585,0)),"") -> Shopping Bag 100% recycled polyester
A32: BAGTOI-MD-BOHMDRM | B32: BAG-TOILETRY | D32: Cosmetic Bag | E32: Bag - Toiletry | F32: =_xlfn.IFNA(INDEX('HS Codes'!$D$2:$K2586,MATCH($B32,'HS Codes'!$A$2:$A2586,0),MATCH(F$1,'HS Codes'!$D$1:$K$1,0)),"") -> 4202929100 | G32: =_xlfn.IFNA(INDEX('HS Codes'!$D$2:$K2586,MATCH($B32,'HS Codes'!$A$2:$A2586,0),MATCH(G$1,'HS Codes'!$D$1:$K$1,0)),"") -> 4202220000 | H32: =_xlfn.IFNA(INDEX('HS Codes'!$D$2:$K2586,MATCH($B32,'HS Codes'!$A$2:$A2586,0),MATCH(H$1,'HS Codes'!$D$1:$K$1,0)),"") -> 0 | I32: =_xlfn.IFNA(INDEX('HS Codes'!$D$2:$K2586,MATCH($B32,'HS Codes'!$A$2:$A2586,0),MATCH(I$1,'HS Codes'!$D$1:$K$1,0)),"") -> 4202929100 | J32: =_xlfn.IFNA(INDEX('HS Codes'!$D$2:$K2586,MATCH($B32,'HS Codes'!$A$2:$A2586,0),MATCH(J$1,'HS Codes'!$D$1:$K$1,0)),"") -> 0 | K32: =_xlfn.IFNA(INDEX('HS Codes'!$D$2:$K2586,MATCH($B32,'HS Codes'!$A$2:$A2586,0),MATCH(K$1,'HS Codes'!$D$1:$K$1,0)),"") -> 0 | L32: =_xlfn.IFNA(INDEX('HS Codes'!$D$2:$K2586,MATCH($B32,'HS Codes'!$A$2:$A2586,0),MATCH(L$1,'HS Codes'!$D$1:$K$1,0)),"") -> 0 | M32: =_xlfn.IFNA(INDEX('HS Codes'!$C$2:$C2586,MATCH($B32,'HS Codes'!$A$2:$A2586,0)),"") -> Toiletry Bag made of 100% polyester
A33: BAGTOI-MD-CACTMNTN | F33: =_xlfn.IFNA(INDEX('HS Codes'!$D$2:$K2587,MATCH($B33,'HS Codes'!$A$2:$A2587,0),MATCH(F$1,'HS Codes'!$D$1:$K$1,0)),"") | G33: =_xlfn.IFNA(INDEX('HS Codes'!$D$2:$K2587,MATCH($B33,'HS Codes'!$A$2:$A2587,0),MATCH(G$1,'HS Codes'!$D$1:$K$1,0)),"") | H33: =_xlfn.IFNA(INDEX('HS Codes'!$D$2:$K2587,MATCH($B33,'HS Codes'!$A$2:$A2587,0),MATCH(H$1,'HS Codes'!$D$1:$K$1,0)),"") | I33: =_xlfn.IFNA(INDEX('HS Codes'!$D$2:$K2587,MATCH($B33,'HS Codes'!$A$2:$A2587,0),MATCH(I$1,'HS Codes'!$D$1:$K$1,0)),"") | J33: =_xlfn.IFNA(INDEX('HS Codes'!$D$2:$K2587,MATCH($B33,'HS Codes'!$A$2:$A2587,0),MATCH(J$1,'HS Codes'!$D$1:$K$1,0)),"") | K33: =_xlfn.IFNA(INDEX('HS Codes'!$D$2:$K2587,MATCH($B33,'HS Codes'!$A$2:$A2587,0),MATCH(K$1,'HS Codes'!$D$1:$K$1,0)),"") | L33: =_xlfn.IFNA(INDEX('HS Codes'!$D$2:$K2587,MATCH($B33,'HS Codes'!$A$2:$A2587,0),MATCH(L$1,'HS Codes'!$D$1:$K$1,0)),"") | M33: =_xlfn.IFNA(INDEX('HS Codes'!$C$2:$C2587,MATCH($B33,'HS Codes'!$A$2:$A2587,0)),"")
A34: BAGTOI-MD-CHRYBMB | B34: BAG-TOILETRY | D34: Cosmetic Bag | E34: Bag - Toiletry | F34: =_xlfn.IFNA(INDEX('HS Codes'!$D$2:$K2588,MATCH($B34,'HS Codes'!$A$2:$A2588,0),MATCH(F$1,'HS Codes'!$D$1:$K$1,0)),"") -> 4202929100 | G34: =_xlfn.IFNA(INDEX('HS Codes'!$D$2:$K2588,MATCH($B34,'HS Codes'!$A$2:$A2588,0),MATCH(G$1,'HS Codes'!$D$1:$K$1,0)),"") -> 4202220000 | H34: =_xlfn.IFNA(INDEX('HS Codes'!$D$2:$K2588,MATCH($B34,'HS Codes'!$A$2:$A2588,0),MATCH(H$1,'HS Codes'!$D$1:$K$1,0)),"") -> 0 | I34: =_xlfn.IFNA(INDEX('HS Codes'!$D$2:$K2588,MATCH($B34,'HS Codes'!$A$2:$A2588,0),MATCH(I$1,'HS Codes'!$D$1:$K$1,0)),"") -> 4202929100 | J34: =_xlfn.IFNA(INDEX('HS Codes'!$D$2:$K2588,MATCH($B34,'HS Codes'!$A$2:$A2588,0),MATCH(J$1,'HS Codes'!$D$1:$K$1,0)),"") -> 0 | K34: =_xlfn.IFNA(INDEX('HS Codes'!$D$2:$K2588,MATCH($B34,'HS Codes'!$A$2:$A2588,0),MATCH(K$1,'HS Codes'!$D$1:$K$1,0)),"") -> 0 | L34: =_xlfn.IFNA(INDEX('HS Codes'!$D$2:$K2588,MATCH($B34,'HS Codes'!$A$2:$A2588,0),MATCH(L$1,'HS Codes'!$D$1:$K$1,0)),"") -> 0 | M34: =_xlfn.IFNA(INDEX('HS Codes'!$C$2:$C2588,MATCH($B34,'HS Codes'!$A$2:$A2588,0)),"") -> Toiletry Bag made of 100% polyester
A35: BAGTOI-MD-PEPPNCH | B35: BAG-TOILETRY | D35: Cosmetic Bag | E35: Bag - Toiletry | F35: =_xlfn.IFNA(INDEX('HS Codes'!$D$2:$K2589,MATCH($B35,'HS Codes'!$A$2:$A2589,0),MATCH(F$1,'HS Codes'!$D$1:$K$1,0)),"") -> 4202929100 | G35: =_xlfn.IFNA(INDEX('HS Codes'!$D$2:$K2589,MATCH($B35,'HS Codes'!$A$2:$A2589,0),MATCH(G$1,'HS Codes'!$D$1:$K$1,0)),"") -> 4202220000 | H35: =_xlfn.IFNA(INDEX('HS Codes'!$D$2:$K2589,MATCH($B35,'HS Codes'!$A$2:$A2589,0),MATCH(H$1,'HS Codes'!$D$1:$K$1,0)),"") -> 0 | I35: =_xlfn.IFNA(INDEX('HS Codes'!$D$2:$K2589,MATCH($B35,'HS Codes'!$A$2:$A2589,0),MATCH(I$1,'HS Codes'!$D$1:$K$1,0)),"") -> 4202929100 | J35: =_xlfn.IFNA(INDEX('HS Codes'!$D$2:$K2589,MATCH($B35,'HS Codes'!$A$2:$A2589,0),MATCH(J$1,'HS Codes'!$D$1:$K$1,0)),"") -> 0 | K35: =_xlfn.IFNA(INDEX('HS Codes'!$D$2:$K2589,MATCH($B35,'HS Codes'!$A$2:$A2589,0),MATCH(K$1,'HS Codes'!$D$1:$K$1,0)),"") -> 0 | L35: =_xlfn.IFNA(INDEX('HS Codes'!$D$2:$K2589,MATCH($B35,'HS Codes'!$A$2:$A2589,0),MATCH(L$1,'HS Codes'!$D$1:$K$1,0)),"") -> 0 | M35: =_xlfn.IFNA(INDEX('HS Codes'!$C$2:$C2589,MATCH($B35,'HS Codes'!$A$2:$A2589,0)),"") -> Toiletry Bag made of 100% polyester
A36: BAGTOI-MD-SEASOIR | B36: BAG-TOILETRY | D36: Cosmetic Bag | E36: Bag - Toiletry | F36: =_xlfn.IFNA(INDEX('HS Codes'!$D$2:$K2590,MATCH($B36,'HS Codes'!$A$2:$A2590,0),MATCH(F$1,'HS Codes'!$D$1:$K$1,0)),"") -> 4202929100 | G36: =_xlfn.IFNA(INDEX('HS Codes'!$D$2:$K2590,MATCH($B36,'HS Codes'!$A$2:$A2590,0),MATCH(G$1,'HS Codes'!$D$1:$K$1,0)),"") -> 4202220000 | H36: =_xlfn.IFNA(INDEX('HS Codes'!$D$2:$K2590,MATCH($B36,'HS Codes'!$A$2:$A2590,0),MATCH(H$1,'HS Codes'!$D$1:$K$1,0)),"") -> 0 | I36: =_xlfn.IFNA(INDEX('HS Codes'!$D$2:$K2590,MATCH($B36,'HS Codes'!$A$2:$A2590,0),MATCH(I$1,'HS Codes'!$D$1:$K$1,0)),"") -> 4202929100 | J36: =_xlfn.IFNA(INDEX('HS Codes'!$D$2:$K2590,MATCH($B36,'HS Codes'!$A$2:$A2590,0),MATCH(J$1,'HS Codes'!$D$1:$K$1,0)),"") -> 0 | K36: =_xlfn.IFNA(INDEX('HS Codes'!$D$2:$K2590,MATCH($B36,'HS Codes'!$A$2:$A2590,0),MATCH(K$1,'HS Codes'!$D$1:$K$1,0)),"") -> 0 | L36: =_xlfn.IFNA(INDEX('HS Codes'!$D$2:$K2590,MATCH($B36,'HS Codes'!$A$2:$A2590,0),MATCH(L$1,'HS Codes'!$D$1:$K$1,0)),"") -> 0 | M36: =_xlfn.IFNA(INDEX('HS Codes'!$C$2:$C2590,MATCH($B36,'HS Codes'!$A$2:$A2590,0)),"") -> Toiletry Bag made of 100% polyester
A37: BALLAST-CAB-NAVY | B37: BALLAST-PILLOW | D37: Ballast x Dock & Bay Pillow | E37: Beach Pillow | F37: =_xlfn.IFNA(INDEX('HS Codes'!$D$2:$K2591,MATCH($B37,'HS Codes'!$A$2:$A2591,0),MATCH(F$1,'HS Codes'!$D$1:$K$1,0)),"") -> 9404.90.2090 | G37: =_xlfn.IFNA(INDEX('HS Codes'!$D$2:$K2591,MATCH($B37,'HS Codes'!$A$2:$A2591,0),MATCH(G$1,'HS Codes'!$D$1:$K$1,0)),"") -> 63079098990 | H37: =_xlfn.IFNA(INDEX('HS Codes'!$D$2:$K2591,MATCH($B37,'HS Codes'!$A$2:$A2591,0),MATCH(H$1,'HS Codes'!$D$1:$K$1,0)),"") -> 3926.90.7500 | I37: =_xlfn.IFNA(INDEX('HS Codes'!$D$2:$K2591,MATCH($B37,'HS Codes'!$A$2:$A2591,0),MATCH(I$1,'HS Codes'!$D$1:$K$1,0)),"") -> 3926.90.7500 | J37: =_xlfn.IFNA(INDEX('HS Codes'!$D$2:$K2591,MATCH($B37,'HS Codes'!$A$2:$A2591,0),MATCH(J$1,'HS Codes'!$D$1:$K$1,0)),"") -> 0 | K37: =_xlfn.IFNA(INDEX('HS Codes'!$D$2:$K2591,MATCH($B37,'HS Codes'!$A$2:$A2591,0),MATCH(K$1,'HS Codes'!$D$1:$K$1,0)),"") -> 6306.40.00 | L37: =_xlfn.IFNA(INDEX('HS Codes'!$D$2:$K2591,MATCH($B37,'HS Codes'!$A$2:$A2591,0),MATCH(L$1,'HS Codes'!$D$1:$K$1,0)),"") -> 0 | M37: =_xlfn.IFNA(INDEX('HS Codes'!$C$2:$C2591,MATCH($B37,'HS Codes'!$A$2:$A2591,0)),"") -> Pillow 100% recycled polyester (no cotton)
